Workbook

Sheet Summary
A1: Party Name | B1: LYKA LABORATORIES LTD. | C1: Date Tolerance | D1: 0 - 15
A2: Reconciliation Period | B2: 01-Apr-2025 to 31-Mar-2026 | C2: TDS Percentage | D2: 0.0 - 10.0
A3: Statement Type | B3: Ledger | C3: Amount Tolerance | D3: 1.0 Rs
A4: Party Type | B4: Vendor
A5: Reconciliation Date | B5: 19-Jun-26 10:16 AM
A7: Reconciliation Statement
A8: Particulars | B8: Annexure | C8: Amount | D8: No. of Entries | E8: Action Required
A9: Closing Balance Difference | C9: =SUM(C10:C11) -> 0 | D9: =SUM(D10:D11) -> 0
A10: Closing Balance as per Company | C10: =-(SUMIFS(Reconciliation!L:L,Reconciliation!D:D,A10,Reconciliation!F:F,"ledger") +SUMIFS(Reconciliation!S:S,Reconciliation!D:D,A10,Reconciliation!M:M,"ledger")) -> 0 | D10: =COUNTIFS(Reconciliation!D:D,A10,Reconciliation!F:F,"ledger") +COUNTIFS(Reconciliation!D:D,A10,Reconciliation!M:M,"ledger") -> 0
A11: Closing Balance as per Party | C11: =-(SUMIFS(Reconciliation!L:L,Reconciliation!D:D,A11,Reconciliation!F:F,"ledger") +SUMIFS(Reconciliation!S:S,Reconciliation!D:D,A11,Reconciliation!M:M,"ledger")) -> 0 | D11: =COUNTIFS(Reconciliation!D:D,A11,Reconciliation!F:F,"ledger") +COUNTIFS(Reconciliation!D:D,A11,Reconciliation!M:M,"ledger") -> 0
A13: Invoice Difference | C13: =SUM(C14:C15) -> 0 | D13: =SUM(D14:D15) -> 0
A14: Invoice not booked by Company | B14: 1 | C14: =SUMIFS(Reconciliation!L:L,Reconciliation!D:D,A14,Reconciliation!F:F,"ledger") +SUMIFS(Reconciliation!S:S,Reconciliation!D:D,A14,Reconciliation!M:M,"ledger") -> 0 | D14: =COUNTIFS(Reconciliation!D:D,A14,Reconciliation!F:F,"ledger") +COUNTIFS(Reconciliation!D:D,A14,Reconciliation!M:M,"ledger") -> 0 | E14: Vendor to provide the invoice copies
A15: Invoice not booked by Party | B15: 10 | C15: =SUMIFS(Reconciliation!L:L,Reconciliation!D:D,A15,Reconciliation!F:F,"ledger") +SUMIFS(Reconciliation!S:S,Reconciliation!D:D,A15,Reconciliation!M:M,"ledger") -> 0 | D15: =COUNTIFS(Reconciliation!D:D,A15,Reconciliation!F:F,"ledger") +COUNTIFS(Reconciliation!D:D,A15,Reconciliation!M:M,"ledger") -> 0 | E15: Vendor to check the reason for invoice not appearing
A16: Debit Note / Credit Note Difference | C16: =SUM(C17:C17) -> 0 | D16: =SUM(D17:D17) -> 0
A17: Credit Note not booked by Company | B17: 23 | C17: =SUMIFS(Reconciliation!L:L,Reconciliation!D:D,A17,Reconciliation!F:F,"ledger") +SUMIFS(Reconciliation!S:S,Reconciliation!D:D,A17,Reconciliation!M:M,"ledger") -> 0 | D17: =COUNTIFS(Reconciliation!D:D,A17,Reconciliation!F:F,"ledger") +COUNTIFS(Reconciliation!D:D,A17,Reconciliation!M:M,"ledger") -> 0 | E17: Company to book the Debit Note and recover from Vendor
A18: Payment / receipt Difference | C18: =SUM(C19:C20) -> 0 | D18: =SUM(D19:D20) -> 0
A19: Payment not booked by Company | B19: 55 | C19: =SUMIFS(Reconciliation!L:L,Reconciliation!D:D,A19,Reconciliation!F:F,"ledger") +SUMIFS(Reconciliation!S:S,Reconciliation!D:D,A19,Reconciliation!M:M,"ledger") -> 0 | D19: =COUNTIFS(Reconciliation!D:D,A19,Reconciliation!F:F,"ledger") +COUNTIFS(Reconciliation!D:D,A19,Reconciliation!M:M,"ledger") -> 0 | E19: Company to book the payment entries
A20: Payment not booked by Party | B20: 61 | C20: =SUMIFS(Reconciliation!L:L,Reconciliation!D:D,A20,Reconciliation!F:F,"ledger") +SUMIFS(Reconciliation!S:S,Reconciliation!D:D,A20,Reconciliation!M:M,"ledger") -> 0 | D20: =COUNTIFS(Reconciliation!D:D,A20,Reconciliation!F:F,"ledger") +COUNTIFS(Reconciliation!D:D,A20,Reconciliation!M:M,"ledger") -> 0 | E20: Vendor to check the payment details
A21: Other Differences | C21: =SUM(C22:C23) -> 0 | D21: =SUM(D22:D23) -> 0
A22: Other entry not booked by Company | B22: 74 | C22: =SUMIFS(Reconciliation!L:L,Reconciliation!D:D,A22,Reconciliation!F:F,"ledger") +SUMIFS(Reconciliation!S:S,Reconciliation!D:D,A22,Reconciliation!M:M,"ledger") -> 0 | D22: =COUNTIFS(Reconciliation!D:D,A22,Reconciliation!F:F,"ledger") +COUNTIFS(Reconciliation!D:D,A22,Reconciliation!M:M,"ledger") -> 0
A23: Other entry not booked by Party | B23: 79 | C23: =SUMIFS(Reconciliation!L:L,Reconciliation!D:D,A23,Reconciliation!F:F,"ledger") +SUMIFS(Reconciliation!S:S,Reconciliation!D:D,A23,Reconciliation!M:M,"ledger") -> 0 | D23: =COUNTIFS(Reconciliation!D:D,A23,Reconciliation!F:F,"ledger") +COUNTIFS(Reconciliation!D:D,A23,Reconciliation!M:M,"ledger") -> 0
A24: TDS / TCS Difference | C24: =SUM(C25:C26) -> 0 | D24: =SUM(D25:D26) -> 0
A25: TDS Booked by Company | B25: 94 | C25: =SUMIFS(Reconciliation!T:T,Reconciliation!D:D,A25) -SUMIFS(Reconciliation!T:T,Reconciliation!D:D,A25,Reconciliation!F:F,"Brought forward",Reconciliation!M:M,"Brought forward") -SUMIFS(Reconciliation!T:T,Reconciliation!D:D,A25,Reconciliation!F:F,"Brought forward",Reconciliation!I:I,"tds") -SUMIFS(Reconciliation!T:T,Reconciliation!D:D,A25,Reconciliation!M:M,"Brought forward",Reconciliation!P:P,"tds") -> 0 | D25: =COUNTIFS(Reconciliation!D:D,A25) -COUNTIFS(Reconciliation!D:D,A25,Reconciliation!F:F,"Brought forward",Reconciliation!M:M,"Brought forward") -COUNTIFS(Reconciliation!D:D,A25,Reconciliation!F:F,"Brought forward",Reconciliation!I:I,"tds") -COUNTIFS(Reconciliation!D:D,A25,Reconciliation!M:M,"Brought forward",Reconciliation!P:P,"tds") -> 0 | E25: Vendor to book the TDS entries
A26: TDS Booked by Party | B26: 94 | C26: =SUMIFS(Reconciliation!T:T,Reconciliation!D:D,A26) -SUMIFS(Reconciliation!T:T,Reconciliation!D:D,A26,Reconciliation!F:F,"Brought forward",Reconciliation!M:M,"Brought forward") -SUMIFS(Reconciliation!T:T,Reconciliation!D:D,A26,Reconciliation!F:F,"Brought forward",Reconciliation!I:I,"tds") -SUMIFS(Reconciliation!T:T,Reconciliation!D:D,A26,Reconciliation!M:M,"Brought forward",Reconciliation!P:P,"tds") -> 0 | D26: =COUNTIFS(Reconciliation!D:D,A26) -COUNTIFS(Reconciliation!D:D,A26,Reconciliation!F:F,"Brought forward",Reconciliation!M:M,"Brought forward") -COUNTIFS(Reconciliation!D:D,A26,Reconciliation!F:F,"Brought forward",Reconciliation!I:I,"tds") -COUNTIFS(Reconciliation!D:D,A26,Reconciliation!M:M,"Brought forward",Reconciliation!P:P,"tds") -> 0 | E26: Vendor to book the TDS entries
A27: Reversal Entries | C27: =SUM(C28:C28) -> 0 | D27: =SUM(D28:D28) -> 0
A28: Reversal Entries | C28: =SUMIFS(Reconciliation!L:L,Reconciliation!D:D,A28,Reconciliation!F:F,"ledger") +SUMIFS(Reconciliation!S:S,Reconciliation!D:D,A28,Reconciliation!M:M,"ledger") -> 0 | D28: =COUNTIFS(Reconciliation!D:D,A28,Reconciliation!F:F,"ledger") +COUNTIFS(Reconciliation!D:D,A28,Reconciliation!M:M,"ledger") -> 0 | E28: No Action Required
A29: Opening Balance Difference | C29: =SUM(C30:C33) -> 0 | D29: =SUM(D30:D33) -> 0
A30: Opening Balance as per Company | C30: =SUMIFS(Reconciliation!L:L,Reconciliation!D:D,A30,Reconciliation!F:F,"ledger") +SUMIFS(Reconciliation!S:S,Reconciliation!D:D,A30,Reconciliation!M:M,"ledger") -> 0 | D30: =COUNTIFS(Reconciliation!D:D,A30,Reconciliation!F:F,"ledger") +COUNTIFS(Reconciliation!D:D,A30,Reconciliation!M:M,"ledger") -> 0
A31: Opening Balance as per Party | C31: =SUMIFS(Reconciliation!L:L,Reconciliation!D:D,A31,Reconciliation!F:F,"ledger") +SUMIFS(Reconciliation!S:S,Reconciliation!D:D,A31,Reconciliation!M:M,"ledger") -> 0 | D31: =COUNTIFS(Reconciliation!D:D,A31,Reconciliation!F:F,"ledger") +COUNTIFS(Reconciliation!D:D,A31,Reconciliation!M:M,"ledger") -> 0 | E31: Vendor to provide the breakup of Opening Balance
A32: Brought forward entries matched - company | B32: 210 | C32: 0 | D32: 0
A33: Brought forward entries matched - party | B33: 211 | C33: 0 | D33: 0
A34: Calculated Balance | C34: =C13+C16+C18+C21+C24+C27+C29 -> 0
A36: Difference | C36: =C9-C34 -> 0

Sheet Reconciliation
A1: Company Id | B1: Party Id | C1: Matched Id | D1: Status | E1: Classification | F1: Company Statement Type | G1: Company Invoice Date | H1: Company Invoice Number | I1: Company DocType | J1: Company Original DocType | K1: Company Narration | L1: Company Amount | M1: Party Statement Type | N1: Party Invoice Date | O1: Party Invoice Number | P1: Party DocType | Q1: Party Original DocType | R1: Party Narration | S1: Party Amount | T1: Difference | U1: Matched Rule | V1: Reco Data & Time | W1: Remark | X1: Party Code | Y1: Daybook Name | Z1: Company Clearing Document Number | AA1: Company Clearing Date | AB1: Company TDS Amount | AC1: Company Posting Date | AD1: Company Code | AE1: Supplier | AF1: Document Number | AG1: Business Area | AH1: Assignment | AI1: Document Header Text | AJ1: Tax Code | AK1: Year/Month | AL1: Reference | AM1: Profit Center | AN1: Posting Date | AO1: Amount in Doc. Curr. | AP1: Document Currency | AQ1: Local Currency | AR1: Entry Date | AS1: Withhldg Tax Base Amount | AT1: Payment Date
A2: 60d2443b-0fb1-44e4-97fe-53fbdfc65b46 | B2: 4b10c103-35ae-417f-b854-efa1a8945391 | C2: 05185f70-d145-3675-9617-30ad2c62d476 | D2: Reconciled | E2: Amount Matched - Recommended | F2: ledger | G2: 21-08-2025 | H2: ANK2526/DBN00007 | I2: invoice | J2: MA | K2: MENOTROPIN IP (GUF) | L2: -817740 | M2: ledger | N2: 31-10-2025 | O2: ANK2526/DBN00007 | P2: creditNote | Q2: CN | S2: 817740 | T2: 0 | U2: SEC-CN1.1-party | V2: 19-Jun-26 10:16 AM | X2: AAACL0820G | Z2: 7053033057 | AB2: 0 | AD2: EPL | AE2: 5906 | AF2: 6000007609 | AG2: EP00 | AH2: ANK2526/DBN00007 | AI2: ANK2526/DBN00007 | AJ2: IA | AK2: 2025/05 | AL2: ELL2 | AM2: 2500 | AN2: 25-08-2025 | AO2: -817740 | AP2: INR | AQ2: INR | AR2: 25-08-2025 | AS2: -693000 | AT2: 21-08-2025
A3: e3064d9b-36d2-47c3-b614-7a93582dac31 | B3: 4bf4f1e8-4ea0-4ebd-a461-51858d4a1d59 | C3: 05f4488d-878f-3ab2-a045-a82fee6d3bcb | D3: TDS Booked by Party | E3: Date and Amount Matched - Recommended | F3: ledger | G3: 16-05-2025 | H3: 7053007500 | I3: payment | J3: KZ | L3: 1359585 | M3: ledger | N3: 16-05-2025 | O3: UTIBN62025051618331475 | P3: payment | Q3: Receipt | S3: -1360800 | T3: -1215 | U3: SEC-PAY3.1-company | V3: 19-Jun-26 10:16 AM | X3: AAACL0820G | Z3: 7053007500 | AB3: 0 | AD3: EPL | AE3: 5276 | AF3: 7053007500 | AG3: EP00 | AH3: 20250516-SJW10 | AI3: 20250516-SJW10 | AK3: 2025/02 | AM3: ENNOVA | AN3: 16-05-2025 | AO3: 1359585 | AP3: INR | AQ3: INR | AR3: 16-05-2025 | AS3: 1215000 | AT3: 16-05-2025
A4: 1db31cc9-1852-40e3-bee5-b9bac353c1f8 | B4: af5535ab-0511-49c1-9292-8a5e1ca4c2b7 | C4: 0ea3ba69-0b5b-3e90-be9d-f02df002b4d7 | D4: Reconciled | E4: Date and Amount Matched | F4: ledger | G4: 25-07-2025 | H4: 7053020673 | I4: payment | J4: KZ | L4: 3940384 | M4: ledger | N4: 25-07-2025 | O4: UTIBR72025072500076328 | P4: payment | Q4: Receipt | S4: -3940384 | T4: 0 | U4: PRI-PAY10.1-company | V4: 19-Jun-26 10:16 AM | X4: AAACL0820G | Z4: 7053020673 | AB4: 0 | AD4: EPL | AE4: 5906 | AF4: 7053020673 | AG4: EP00 | AH4: 20250725-SJH10 | AI4: 20250725-SJH10 | AK4: 2025/04 | AM4: XENNEA | AN4: 25-07-2025 | AO4: 3940384 | AP4: INR | AQ4: INR | AR4: 25-07-2025 | AS4: 3518200 | AT4: 25-07-2025
A5: 06b4cbc1-df7c-4dc2-a5e5-e3ed11468e91 | B5: 45a5cece-d771-4b25-a062-d0c539fffa26 | C5: 1395c5ae-873f-3f8b-ae53-ab71616636e5 | D5: TDS Booked by Party | E5: Multiple Based on Date | F5: ledger | G5: 08-10-2025 | H5: 7053032927 | I5: payment | J5: KZ | L5: 99742 | M5: ledger | N5: 08-10-2025 | O5: UTIBR72025100800060307 | P5: payment | Q5: Receipt | S5: -258892 | T5: 0 | U5: PRI-PAY5.2-company | V5: 19-Jun-26 10:16 AM | X5: AAACL0820G | Z5: 7053032927 | AB5: 0 | AD5: EPL | AE5: 5159 | AF5: 7053032927 | AG5: EP00 | AH5: 20251008-SJH10 | AI5: 20251008-SJH10 | AK5: 2025/07 | AM5: 2500 | AN5: 08-10-2025 | AO5: 99742 | AP5: INR | AQ5: INR | AR5: 08-10-2025 | AS5: 90675 | AT5: 08-10-2025
A6: 77c42784-11ca-4039-a04e-9fc050e211d9 | B6: c0ac7d01-7b9c-40c6-abca-c0fdf6d3a1c1 | C6: 1395c5ae-873f-3f8b-ae53-ab71616636e5 | D6: TDS Booked by Party | E6: Multiple Based on Date | F6: ledger | G6: 08-10-2025 | H6: 7053032930 | I6: payment | J6: KZ | L6: 257573.8 | M6: ledger | N6: 08-10-2025 | O6: AXISCN1112025593 | P6: payment | Q6: Receipt | S6: -101556 | T6: 0 | U6: PRI-PAY5.2-company | V6: 19-Jun-26 10:16 AM | X6: AAACL0820G | Z6: 7053032930 | AB6: 0 | AD6: EPL | AE6: 5276 | AF6: 7053032930 | AG6: EP00 | AH6: 20251008-SJH10 | AI6: 20251008-SJH10 | AK6: 2025/07 | AM6: 2500 | AN6: 08-10-2025 | AO6: 257573.8 | AP6: INR | AQ6: INR | AR6: 08-10-2025 | AS6: 222190 | AT6: 08-10-2025
A7: c9413937-a0a2-440e-afed-243116b6bb39 | B7: e052f7df-7a34-409c-820d-426b4b035581 | C7: 1395c5ae-873f-3f8b-ae53-ab71616636e5 | D7: TDS Booked by Party | E7: Multiple Based on Date | F7: ledger | G7: 08-10-2025 | H7: 7053033057 | I7: payment | J7: KZ | L7: 817740 | M7: ledger | N7: 08-10-2025 | O7: AXISCN1112157656 | P7: payment | Q7: Receipt | S7: -817740 | T7: -3132.2 | U7: PRI-PAY5.2-company | V7: 19-Jun-26 10:16 AM | X7: AAACL0820G | Z7: 7053033057 | AB7: 0 | AD7: EPL | AE7: 5906 | AF7: 7053033057 | AG7: EP00 | AH7: 20251008-MSESJ | AI7: 20251008-MSESJ | AK7: 2025/07 | AM7: 2500 | AN7: 08-10-2025 | AO7: 817740 | AP7: INR | AQ7: INR | AR7: 08-10-2025 | AS7: 693000 | AT7: 08-10-2025
A8: ee54b17a-3187-41c3-ad47-a9f5f3bb14a8 | B8: f1fc1d2c-fb00-477d-8a75-09008d81a667 | C8: 16fef953-aaae-3c19-8966-746b3c3f8cfe | D8: Reconciled | E8: Invoice Number Matched | F8: ledger | G8: 30-04-2025 | H8: ANK2526/GIS00091 | I8: invoice | J8: MF | K8: MATERNA DEPOT 3.75 MG INJ.[P2P]NSCH-ONCO | L8: -3940384 | M8: ledger | N8: 30-04-2025 | O8: ANK2526/GIS00091 | P8: invoice | Q8: Sale | S8: 3940384 | T8: 0 | U8: PRI-INV1.5_A-company | V8: 19-Jun-26 10:16 AM | X8: AAACL0820G | Z8: 7053020673 | AB8: 0 | AD8: EPL | AE8: 5906 | AF8: 6006000193 | AG8: EP00 | AH8: ANK2526/GIS00091 | AI8: ANK2526/GIS00091 | AJ8: I1 | AK8: 2025/02 | AL8: EMHC | AM8: XENNEA | AN8: 13-05-2025 | AO8: -3940384 | AP8: INR | AQ8: INR | AR8: 13-05-2025 | AS8: -3518200 | AT8: 12-05-2025
A9: 017f564b-f905-4d5a-9000-0baf92ea446c | B9: 9a50f4c0-c21a-4aad-960a-713d5c03e0b6 | C9: 1991f216-b6cf-4890-8202-8b48ceaa8400 | D9: TDS Booked by Party | E9: Payment Matched - Recommended | F9: ledger | G9: 24-09-2025 | H9: 7053030340 | I9: payment | J9: KZ | L9: 1024095.5 | M9: ledger | N9: 25-09-2025 | O9: AXISCN1096036481 | P9: payment | Q9: Receipt | S9: -1042715.5 | T9: -18620 | U9: SEC-PAY4.1-company | V9: 19-Jun-26 10:16 AM | X9: AAACL0820G | Z9: 7053030340 | AB9: 0 | AD9: EPL | AE9: 5159 | AF9: 7053030340 | AG9: EP00 | AH9: 20250924-MSMSJ | AI9: 20250924-MSMSJ | AK9: 2025/06 | AM9: 2500 | AN9: 24-09-2025 | AO9: 1024095.52 | AP9: INR | AQ9: INR | AR9: 24-09-2025 | AS9: 930996 | AT9: 24-09-2025
A10: 524bc8e0-a4a8-42e8-b23d-c1f23686de5a | B10: 186ecf5a-6b8f-46dc-affc-8da4ff6898d7 | C10: 23202ed6-9dcb-4c15-beab-145bc4a547de | D10: TDS Booked by Party | E10: Payment Matched - Recommended | F10: ledger | G10: 22-01-2026 | H10: 7053054141 | I10: payment | J10: KZ | L10: 413433 | M10: ledger | N10: 23-01-2026 | O10: UTIBR72026012300040395 | P10: payment | Q10: Receipt | S10: -413827 | T10: -394 | U10: SEC-PAY4.1-company | V10: 19-Jun-26 10:16 AM | X10: AAACL0820G | Z10: 7053054141 | AB10: 0 | AD10: EPL | AE10: 5276 | AF10: 7053054141 | AG10: EP00 | AH10: 20260122-SJW10 | AI10: 20260122-SJW10 | AK10: 2025/10 | AM10: ENNOVA | AN10: 22-01-2026 | AO10: 413433 | AP10: INR | AQ10: INR | AR10: 22-01-2026 | AS10: 394120.94 | AT10: 22-01-2026
A11: 4496d1c4-1e8a-4d2d-968c-d797ac14155c | B11: 03c26d9f-6c72-4e5f-bfec-675ae5dc3ecd | C11: 2399b5aa-899a-3e44-8e5f-4d09a538a2c3 | D11: TDS Booked by Company | E11: Invoice Number Matched | F11: ledger | G11: 21-04-2025 | H11: ANK2526/SER00001 | I11: invoice | J11: MI | K11: 421111714 MATERNA - HCG 5000 IU | L11: -1860607 | M11: ledger | N11: 21-04-2025 | O11: ANK2526/SER00001 | P11: invoice | Q11: Other | S11: 1894233.6 | T11: 33626.6 | U11: PRI-INV1.6-company | V11: 19-Jun-26 10:16 AM | X11: AAACL0820G | Z11: 7053012813 | AB11: -33626 | AD11: EPL | AE11: 5159 | AF11: 6008004363 | AG11: EP00 | AH11: ANK2526/SER00001 | AI11: ANK2526/SER00001 | AJ11: IA | AK11: 2025/02 | AL11: ELL2 | AM11: 2500 | AN11: 16-05-2025 | AO11: -1860607 | AP11: INR | AQ11: INR | AR11: 16-05-2025 | AS11: -1681280 | AT11: 21-05-2025
A12: 1bdafe07-41ec-47b3-baed-36acb746303a | B12: 3c3607e3-b64d-4e2d-8c7c-98b4f01adbac | C12: 252dae23-d549-3aa6-a82d-35d32098b55f | D12: TDS Booked by Company | E12: Invoice Number Matched | F12: ledger | G12: 29-01-2026 | H12: ANK2526/GIS00934 | I12: invoice | J12: MF | K12: REBEZ IV INJECTION [P TO P] | L12: -1370813 | M12: ledger | N12: 29-01-2026 | O12: ANK2526/GIS00934 | P12: invoice | Q12: Sale | S12: 1372120 | T12: 1307 | U12: PRI-INV1.6-company | V12: 19-Jun-26 10:16 AM | X12: AAACL0820G | Z12: 7053002431 | AB12: -1307 | AD12: EPL | AE12: 5276 | AF12: 6006002082 | AG12: EP00 | AH12: ANK2526/GIS00934 | AI12: ANK2526/GIS00934 | AJ12: I3 | AK12: 2025/11 | AL12: EMHC | AM12: ENNOVA | AN12: 02-02-2026 | AO12: -1370813 | AP12: INR | AQ12: INR | AR12: 02-02-2026 | AS12: -1306780.94 | AT12: 30-01-2026
A13: 823a6688-4523-4a8e-9948-a9933e848717 | B13: 8c1a1eab-34db-4f50-8dd1-f0029d456470 | C13: 272317a6-3e17-325e-9f62-8625bbbb07c3 | D13: TDS Booked by Party | E13: Multiple Based on Date | F13: ledger | G13: 21-01-2026 | H13: 7053053702 | I13: payment | J13: KZ | L13: 594152 | M13: ledger | N13: 21-01-2026 | O13: UTIBR72026012100004817 | P13: payment | Q13: Receipt | S13: -604396 | T13: 0 | U13: PRI-PAY5.2-company | V13: 19-Jun-26 10:16 AM | X13: AAACL0820G | Z13: 7053053702 | AB13: 0 | AD13: EPL | AE13: 5276 | AF13: 7053053702 | AG13: EP00 | AH13: 20260121-SJH10 | AI13: 20260121-SJH10 | AK13: 2025/10 | AM13: 2500 | AN13: 21-01-2026 | AO13: 594152 | AP13: INR | AQ13: INR | AR13: 21-01-2026 | AS13: 512200 | AT13: 21-01-2026
A14: af58096c-cbad-44b4-b5a8-a14cd3630f2b | B14: 95c1917c-7ae0-4de2-b5f4-d43cd30002ab | C14: 272317a6-3e17-325e-9f62-8625bbbb07c3 | D14: TDS Booked by Party | E14: Multiple Based on Date | F14: ledger | G14: 21-01-2026 | H14: 7053053708 | I14: payment | J14: KZ | L14: 3398760 | M14: ledger | N14: 21-01-2026 | O14: UTIBR72026012100004816 | P14: payment | Q14: Receipt | S14: -3402000 | T14: -13484 | U14: PRI-PAY5.2-company | V14: 19-Jun-26 10:16 AM | X14: AAACL0820G | Z14: 7053053708 | AB14: 0 | AD14: EPL | AE14: 5906 | AF14: 7053053708 | AG14: EP00 | AH14: 20260121-SJH10 | AI14: 20260121-SJH10 | AK14: 2025/10 | AM14: CRITI_CARE | AN14: 21-01-2026 | AO14: 3398760 | AP14: INR | AQ14: INR | AR14: 21-01-2026 | AS14: 3240000 | AT14: 21-01-2026
A15: 450bd921-1a8d-4845-b2ae-bf1216fd9198 | B15: 2eff2df9-aac2-4397-a9c7-638e6ac9253a | C15: 2a78bd4d-795a-39e0-b2e2-25d82ab37a71 | D15: TDS Booked by Company | E15: Invoice Number Matched | F15: ledger | G15: 16-03-2026 | H15: ANK2526/SER00080 | I15: invoice | J15: MI | K15: 421111716 MATERNA - HMG 75 IU | L15: -1372125 | M15: ledger | N15: 16-03-2026 | O15: ANK2526/SER00080 | P15: invoice | Q15: Other | S15: 1398768 | T15: 26643 | U15: PRI-INV1.6-company | V15: 19-Jun-26 10:16 AM | X15: AAACL0820G | AB15: -26643 | AD15: EPL | AE15: 5159 | AF15: 6008042702 | AG15: EP00 | AH15: ANK2526/SER00080 | AI15: ANK2526/SER00080 | AJ15: IG | AK15: 2025/12 | AL15: ELL2 | AM15: 2500 | AN15: 20-03-2026 | AO15: -1372125 | AP15: INR | AQ15: INR | AR15: 20-03-2026 | AS15: -1332160 | AT15: 02-04-2026
A16: bfacda10-298a-45fb-a0b8-561ea38f192b | B16: d7ed3f6c-6931-4855-85b0-e1359d7f45cc | C16: 2f904425-1935-38d4-b518-fd53aca1c625 | D16: TDS Booked by Company | E16: Invoice Number Matched | F16: ledger | G16: 26-06-2025 | H16: ANK2526/SER00025 | I16: invoice | J16: MI | K16: 420002214 PANPURE I.V. 20 MG DO | L16: -508860 | M16: ledger | N16: 26-06-2025 | O16: ANK2526/SER00025 | P16: invoice | Q16: Other | S16: 518112 | T16: 9252 | U16: PRI-INV1.6-company | V16: 19-Jun-26 10:16 AM | X16: AAACL0820G | Z16: 7053031634 | AB16: -9252 | AD16: EPL | AE16: 5159 | AF16: 6008010168 | AG16: EP00 | AH16: ANK2526/SER00025 | AI16: ANK2526/SER00025 | AJ16: IA | AK16: 2025/04 | AL16: ELL2 | AM16: 2500 | AN16: 01-07-2025 | AO16: -508860 | AP16: INR | AQ16: INR | AR16: 01-07-2025 | AS16: -462600 | AT16: 15-07-2025
A17: ffb7e322-b11e-418d-8624-0c78428ff4bc | B17: 5ce800c0-06e5-4125-a988-a782f27d2933 | C17: 30c02a2c-73e5-4135-843c-26b6c22ef8ec | D17: TDS Booked by Party | E17: Multiple Based on Invoice Number and Date Range | F17: ledger | G17: 26-05-2025 | H17: 7053009079 | I17: payment | J17: KZ | L17: 1812780 | M17: ledger | N17: 30-05-2025 | O17: AXISCN0983739554 | P17: payment | Q17: Receipt | S17: -1816778.9 | T17: 0 | U17: PRI-PAY13.1-company | V17: 19-Jun-26 10:16 AM | X17: AAACL0820G | Z17: 7053009079 | AB17: 0 | AD17: EPL | AE17: 5276 | AF17: 7053009079 | AG17: EP00 | AH17: 20250526-SJW01 | AI17: 20250526-SJW01 | AK17: 2025/02 | AM17: ENNOVA | AN17: 26-05-2025 | AO17: 1812780 | AP17: INR | AQ17: INR | AR17: 26-05-2025 | AS17: 1620000 | AT17: 26-05-2025
B18: c3e2afb1-e631-4f35-9c16-28866885aed8 | C18: 30c02a2c-73e5-4135-843c-26b6c22ef8ec | D18: TDS Booked by Party | E18: Multiple Based on Invoice Number and Date Range | F18: ledger | L18: 0 | M18: ledger | N18: 30-05-2025 | O18: AXISCN0983739555 | P18: payment | Q18: Receipt | S18: -624.96 | T18: -4623.84 | U18: PRI-PAY13.1-company | V18: 19-Jun-26 10:16 AM | X18: AAACL0820G | AB18: 0
A19: 19cf0320-a7d6-4632-93f9-3aa8ebabefda | B19: 356677a1-0763-4f5f-b67d-9fa67464a66e | C19: 33b8f008-c93f-3a19-a5a5-37851b94ef77 | D19: TDS Booked by Company | E19: Invoice Number Matched | F19: ledger | G19: 10-12-2025 | H19: ANK2526/GIS00839 | I19: invoice | J19: MF | K19: REBEZ IV INJECTION [P TO P] | L19: -1666450 | M19: ledger | N19: 10-12-2025 | O19: ANK2526/GIS00839 | P19: invoice | Q19: Sale | S19: 1668039 | T19: 1589 | U19: PRI-INV1.6-company | V19: 19-Jun-26 10:16 AM | X19: AAACL0820G | Z19: 7053058597 | AB19: -1589 | AD19: EPL | AE19: 5276 | AF19: 6006001732 | AG19: EP00 | AH19: ANK2526/GIS00839 | AI19: ANK2526/GIS00839 | AJ19: I3 | AK19: 2025/09 | AL19: EMHC | AM19: ENNOVA | AN19: 19-12-2025 | AO19: -1666450 | AP19: INR | AQ19: INR | AR19: 19-12-2025 | AS19: -1588608.56 | AT19: 11-12-2025
A20: e2c99a70-4d15-48ef-b920-e2e1303ed043 | B20: dfa78401-46da-4c19-8814-55f73efb5a9d | C20: 3a6a07f5-c8d0-3111-8209-202a899a258e | D20: TDS Booked by Party | E20: Date and Amount Matched - Recommended | F20: ledger | G20: 12-02-2026 | H20: 7053058597 | I20: payment | J20: KZ | L20: 1666450 | M20: ledger | N20: 12-02-2026 | O20: UTIBR72026021200092359 | P20: payment | Q20: Receipt | S20: -1668039 | T20: -1589 | U20: SEC-PAY3.1-company | V20: 19-Jun-26 10:16 AM | X20: AAACL0820G | Z20: 7053058597 | AB20: 0 | AD20: EPL | AE20: 5276 | AF20: 7053058597 | AG20: EP00 | AH20: 20260212-SJW10 | AI20: 20260212-SJW10 | AK20: 2025/11 | AM20: ENNOVA | AN20: 12-02-2026 | AO20: 1666450 | AP20: INR | AQ20: INR | AR20: 12-02-2026 | AS20: 1588608.56 | AT20: 12-02-2026
A21: 31bbc752-4579-4f0a-8c60-93d9f4763baa | B21: 81bba397-4096-40c8-b7e2-b7017396a2d5 | C21: 4121dcea-21e1-39ea-b2ae-617ac8d404e6 | D21: TDS Booked by Company | E21: Invoice Number Matched | F21: ledger | G21: 27-11-2025 | H21: ANK2526/GIS00786 | I21: invoice | J21: MF | K21: EMTIG INJECTION [P TO P] | L21: -1707537 | M21: ledger | N21: 27-11-2025 | O21: ANK2526/GIS00786 | P21: invoice | Q21: Sale | S21: 1709165 | T21: 1628 | U21: PRI-INV1.6-company | V21: 19-Jun-26 10:16 AM | X21: AAACL0820G | Z21: 7053053708 | AB21: -1628 | AD21: EPL | AE21: 5906 | AF21: 6006001720 | AG21: EP00 | AH21: ANK2526/GIS00786 | AI21: ANK2526/GIS00786 | AJ21: I3 | AK21: 2025/09 | AL21: EMHC | AM21: CRITI_CARE | AN21: 19-12-2025 | AO21: -1707537 | AP21: INR | AQ21: INR | AR21: 19-12-2025 | AS21: -1627776.2 | AT21: 06-12-2025
A22: 01b0bfca-76c7-41e4-b373-b8f58d7c5a86 | B22: 1e1bce79-95dd-4cc6-8b1b-ff4d93cc6372 | C22: 4d6f23b7-dd76-3d73-b15f-1e43a867c178 | D22: TDS Booked by Party | E22: Date and Amount Matched - Recommended | F22: ledger | G22: 17-04-2025 | H22: 7053002545 | I22: payment | J22: KZ | L22: 7298494 | M22: ledger | N22: 17-04-2025 | O22: UTIBR72025041700038257 | P22: payment | Q22: Receipt | S22: -7305016 | T22: -6522 | U22: SEC-PAY3.1-company | V22: 19-Jun-26 10:16 AM | X22: AAACL0820G | Z22: 7053002545 | AB22: 0 | AD22: EPL | AE22: 5906 | AF22: 7053002545 | AG22: EP00 | AH22: 20250417-SJH10 | AI22: 20250417-SJH10 | AK22: 2025/01 | AM22: CRITI_CARE | AN22: 17-04-2025 | AO22: 7298494 | AP22: INR | AQ22: INR | AR22: 17-04-2025 | AS22: 6522335.6799999997 | AT22: 17-04-2025
A23: 168a257c-6f08-46b6-9608-0725e376ecba | B23: 4cabb64d-c453-46f4-808e-9156760af86e | C23: 5a843abf-e9ca-324c-afd1-0dedba4227f0 | D23: TDS Booked by Company | E23: Invoice Number Matched | F23: ledger | G23: 26-11-2025 | H23: ANK2526/GIS00781 | I23: invoice | J23: MF | K23: REBEZ IV INJECTION [P TO P] | L23: -292718 | M23: ledger | N23: 26-11-2025 | O23: ANK2526/GIS00781 | P23: invoice | Q23: Sale | S23: 292997 | T23: 279 | U23: PRI-INV1.6-company | V23: 19-Jun-26 10:16 AM | X23: AAACL0820G | Z23: 7053054141 | AB23: -279 | AD23: EPL | AE23: 5276 | AF23: 6006001724 | AG23: EP00 | AH23: ANK2526/GIS00781 | AI23: ANK2526/GIS00781 | AJ23: I3 | AK23: 2025/09 | AL23: EMHC | AM23: ENNOVA | AN23: 19-12-2025 | AO23: -292718 | AP23: INR | AQ23: INR | AR23: 19-12-2025 | AS23: -279044.75 | AT23: 08-12-2025
A24: 7c3db2b5-709b-419a-9fee-1ff7747aea8a | B24: 6a61b6ee-0eba-480f-ba9a-db85633f5e91 | C24: 5c4816a8-ac14-3e72-9090-a3b72bad22e7 | D24: TDS Booked by Party | E24: Date and Amount Matched - Recommended | F24: ledger | G24: 01-10-2025 | H24: 7053031634 | I24: payment | J24: KZ | L24: 1070387 | M24: ledger | N24: 01-10-2025 | O24: AXISCN1103265077 | P24: payment | Q24: Receipt | S24: -1089849.6 | T24: -19462.6 | U24: SEC-PAY3.1-company | V24: 19-Jun-26 10:16 AM | X24: AAACL0820G | Z24: 7053031634 | AB24: 0 | AD24: EPL | AE24: 5159 | AF24: 7053031634 | AG24: EP00 | AH24: 20251001-SJH11 | AI24: 20251001-SJH11 | AK24: 2025/07 | AM24: 2500 | AN24: 01-10-2025 | AO24: 1070387 | AP24: INR | AQ24: INR | AR24: 01-10-2025 | AS24: 973080 | AT24: 01-10-2025
A25: 40a85208-dcf4-496e-bfaa-a1aa50d87efd | B25: 412b0cf1-2b9a-4f3d-b552-fb96018b8efd | C25: 5e3d74eb-1238-31a5-b9ea-68850a0ee4b8 | D25: TDS Booked by Company | E25: Invoice Number Matched | F25: ledger | G25: 21-08-2025 | H25: ANK2526/SER00049 | I25: invoice | J25: KR | K25: LYKA RATE DIFFERENCE | L25: -99742 | M25: ledger | N25: 21-08-2025 | O25: ANK2526/SER00049 | P25: invoice | Q25: Other | S25: 101556 | T25: 1814 | U25: PRI-INV1.6-company | V25: 19-Jun-26 10:16 AM | X25: AAACL0820G | Z25: 7053032927 | AB25: -1814 | AD25: EPL | AE25: 5159 | AF25: 7043041053 | AG25: EP00 | AH25: ANK2526/SER00049 | AJ25: IH | AK25: 2025/06 | AL25: 2025159442 | AM25: 2500 | AN25: 10-09-2025 | AO25: -99742 | AP25: INR | AQ25: INR | AR25: 10-09-2025 | AS25: -90675 | AT25: 25-09-2025
A26: d1150970-655c-4d2c-b033-cd90711105ce | B26: e95e28a5-d3f0-4f82-9ff8-0b8b5698664d | C26: 60345083-22dc-399c-9caf-fadd92d4175f | D26: TDS Booked by Party | E26: Date and Amount Matched - Recommended | F26: ledger | G26: 10-10-2025 | H26: 7053033678 | I26: payment | J26: KZ | L26: 2460902 | M26: ledger | N26: 10-10-2025 | O26: AXISCN1114230662 | P26: payment | Q26: Receipt | S26: -2505646.1 | T26: -44744.08 | U26: SEC-PAY3.1-company | V26: 19-Jun-26 10:16 AM | X26: AAACL0820G | Z26: 7053033678 | AB26: 0 | AD26: EPL | AE26: 5159 | AF26: 7053033678 | AG26: EP00 | AH26: 20251010-MSMSJ | AI26: 20251010-MSMSJ | AK26: 2025/07 | AM26: 2500 | AN26: 10-10-2025 | AO26: 2460902 | AP26: INR | AQ26: INR | AR26: 10-10-2025 | AS26: 2237184 | AT26: 10-10-2025
A27: 25c35bca-1693-4cb9-90b0-065e84c3251d | B27: e2f002de-023e-4431-af63-6f673f3fc3cb | C27: 61a89e37-90ac-4087-8224-63e799811c06 | D27: TDS Booked by Party | E27: Payment Matched - Recommended | F27: ledger | G27: 17-10-2025 | H27: 7053036126 | I27: payment | J27: KZ | L27: 3917289 | M27: ledger | N27: 18-10-2025 | O27: AXISCN1122982304 | P27: payment | Q27: Receipt | S27: -3920000 | T27: -2711 | U27: SEC-PAY4.1-company | V27: 19-Jun-26 10:16 AM | X27: AAACL0820G | Z27: 7053036126 | AB27: 0 | AD27: EPL | AE27: 5906 | AF27: 7053036126 | AG27: EP00 | AH27: 20251017-MSESJ | AI27: 20251017-MSESJ | AK27: 2025/07 | AM27: XENNEA | AN27: 17-10-2025 | AO27: 3917289 | AP27: INR | AQ27: INR | AR27: 17-10-2025 | AS27: 3500000 | AT27: 17-10-2025
A28: 5d4248ec-7a4e-4fcd-bcc9-3fa3cbd79825 | B28: 80f49ab0-4efa-4eda-b1aa-723f9a2e2702 | C28: 7515671b-9a76-3276-8caa-36e894b60403 | D28: TDS Booked by Company | E28: Invoice Number Matched | F28: ledger | G28: 30-11-2025 | H28: ANK2526/GIS00823 | I28: invoice | J28: MF | K28: REBEZ IV INJECTION [P TO P] | L28: -834164 | M28: ledger | N28: 30-11-2025 | O28: ANK2526/GIS00823 | P28: invoice | Q28: Sale | S28: 834959 | T28: 795 | U28: PRI-INV1.6-company | V28: 19-Jun-26 10:16 AM | X28: AAACL0820G | Z28: 7053055928 | AB28: -795 | AD28: EPL | AE28: 5276 | AF28: 6006001769 | AG28: EP00 | AH28: ANK2526/GIS00823 | AI28: ANK2526/GIS00823 | AJ28: I3 | AK28: 2025/09 | AL28: EMHC | AM28: ENNOVA | AN28: 22-12-2025 | AO28: -834164 | AP28: INR | AQ28: INR | AR28: 22-12-2025 | AS28: -795199.06 | AT28: 11-12-2025
A29: e88999b1-05ec-4268-bbbc-5119f6a8b867 | B29: 3df3999c-3eae-447e-86eb-ace45ffe1656 | C29: 7969e88d-93c3-3ac6-a71b-a5a023490392 | D29: TDS Booked by Company | E29: Invoice Number Matched | F29: ledger | G29: 31-10-2025 | H29: ANK2526/GIS00697 | I29: invoice | J29: MF | K29: EMTIG INJECTION [P TO P] | L29: -3480330 | M29: ledger | N29: 31-10-2025 | O29: ANK2526/GIS00697 | P29: invoice | Q29: Sale | S29: 3483648 | T29: 3318 | U29: PRI-INV1.6-company | V29: 19-Jun-26 10:16 AM | X29: AAACL0820G | Z29: 7053052271 | AB29: -3318 | AD29: EPL | AE29: 5906 | AF29: 6006001534 | AG29: EP00 | AH29: ANK2526/GIS00697 | AI29: ANK2526/GIS00697 | AJ29: I3 | AK29: 2025/08 | AL29: EMHC | AM29: CRITI_CARE | AN29: 19-11-2025 | AO29: -3480330 | AP29: INR | AQ29: INR | AR29: 19-11-2025 | AS29: -3317760 | AT29: 13-11-2025
A30: 74df1aa3-bc82-40e6-b13c-9ad2dd46ec10 | B30: d151a706-c557-4177-ace4-ad6f0c530f1d | C30: 7f4b4023-d438-3660-b28b-f92d110c9b33 | D30: TDS Booked by Company | E30: Invoice Number Matched | F30: ledger | G30: 19-07-2025 | H30: ANK2526/SER00034 | I30: invoice | J30: MI | K30: 421111715 MATERNA - HCG 10000 | L30: -561527 | M30: ledger | N30: 19-07-2025 | O30: ANK2526/SER00034 | P30: invoice | Q30: Other | S30: 571737.6 | T30: 10210.6 | U30: PRI-INV1.6-company | V30: 19-Jun-26 10:16 AM | X30: AAACL0820G | Z30: 7053031634 | AB30: -10210 | AD30: EPL | AE30: 5159 | AF30: 6008014035 | AG30: EP00 | AH30: ANK2526/SER00034 | AI30: ANK2526/SER00034 | AJ30: IA | AK30: 2025/04 | AL30: ELP3 | AM30: 2500 | AN30: 31-07-2025 | AO30: -561527 | AP30: INR | AQ30: INR | AR30: 31-07-2025 | AS30: -510480 | AT30: 13-08-2025
A31: feffc451-9eb3-4171-8faf-000859405a38 | B31: fad17af0-baf0-4352-a9e7-25d790de30fe | C31: 80ae845c-e9fa-33be-bd86-890140fe421e | D31: TDS Booked by Company | E31: Invoice Number Matched | F31: ledger | G31: 26-11-2025 | H31: ANK2526/GIS00782 | I31: invoice | J31: MF | K31: REBEZ IV INJECTION [P TO P] | L31: -120715 | M31: ledger | N31: 26-11-2025 | O31: ANK2526/GIS00782 | P31: invoice | Q31: Sale | S31: 120830 | T31: 115 | U31: PRI-INV1.6-company | V31: 19-Jun-26 10:16 AM | X31: AAACL0820G | Z31: 7053054141 | AB31: -115 | AD31: EPL | AE31: 5276 | AF31: 6006001725 | AG31: EP00 | AH31: ANK2526/GIS00782 | AI31: ANK2526/GIS00782 | AJ31: I3 | AK31: 2025/09 | AL31: EMHC | AM31: ENNOVA | AN31: 19-12-2025 | AO31: -120715 | AP31: INR | AQ31: INR | AR31: 19-12-2025 | AS31: -115076.19 | AT31: 08-12-2025
A32: bc391e80-a6e0-453d-a423-c7da6adc84f0 | B32: c81bf6c0-b64d-488b-bee6-59e4ad1faaec | C32: 9286c9af-9bb2-3567-b2b7-fdf0c45b4115 | D32: TDS Booked by Party | E32: Multiple Based on Invoice Number | F32: ledger | G32: 14-01-2026 | H32: 7053052271 | I32: payment | J32: KZ | L32: 3480330 | M32: ledger | N32: 14-01-2026 | O32: UTIBR72026011400000543 | P32: payment | Q32: Receipt | S32: -232460 | T32: 0 | U32: PRI-PAY5.1-company | V32: 19-Jun-26 10:16 AM | X32: AAACL0820G | Z32: 7053052271 | AB32: 0 | AD32: EPL | AE32: 5906 | AF32: 7053052271 | AG32: EP00 | AH32: 20260114-SJH01 | AI32: 20260114-SJH01 | AK32: 2025/10 | AM32: CRITI_CARE | AN32: 14-01-2026 | AO32: 3480330 | AP32: INR | AQ32: INR | AR32: 14-01-2026 | AS32: 3317760 | AT32: 14-01-2026
B33: f1bfb71a-578f-499f-b334-3d225c80979b | C33: 9286c9af-9bb2-3567-b2b7-fdf0c45b4115 | D33: TDS Booked by Party | E33: Multiple Based on Invoice Number | F33: ledger | L33: 0 | M33: ledger | N33: 14-01-2026 | O33: UTIBR72026011400000544 | P33: payment | Q33: Receipt | S33: -3483648 | T33: -235778 | U33: PRI-PAY5.1-company | V33: 19-Jun-26 10:16 AM | X33: AAACL0820G | AB33: 0
A34: 70d5264b-d33f-4983-93dd-ef6ff1535b45 | B34: 363f9169-6096-452e-9b08-14f89e80ab75 | C34: 96ca066f-f3dd-31d1-8565-a73b4c76be09 | D34: TDS Booked by Company | E34: Invoice Number Matched | F34: ledger | G34: 02-08-2025 | H34: ANK2526/SER00045 | I34: invoice | J34: MI | K34: Job Work Charge - AUG 2025 | L34: -1227.92 | M34: ledger | N34: 02-08-2025 | O34: ANK2526/SER00045 | P34: invoice | Q34: Other | S34: 1249.92 | T34: 22 | U34: PRI-INV1.6-company | V34: 19-Jun-26 10:16 AM | X34: AAACL0820G | Z34: 7053032930 | AB34: -22 | AD34: EPL | AE34: 5276 | AF34: 6008018400 | AG34: EP00 | AH34: ANK2526/SER00045 | AI34: ANK2526/SER00045 | AJ34: IA | AK34: 2025/06 | AL34: EGUA | AM34: 2500 | AN34: 18-09-2025 | AO34: -1227.92 | AP34: INR | AQ34: INR | AR34: 18-09-2025 | AS34: -1116 | AT34: 29-08-2025
A35: 72d032ec-9e10-4e0c-9d88-adf0df871a90 | B35: f3934940-c201-4051-9bf2-3ce66b5a27b5 | C35: 9b7b3f14-1268-37bd-8f97-a800357d4974 | D35: TDS Booked by Party | E35: Date and Amount Matched - Recommended | F35: ledger | G35: 30-01-2026 | H35: 7053055928 | I35: payment | J35: KZ | L35: 834164 | M35: ledger | N35: 30-01-2026 | O35: AXISCN1235469725 | P35: payment | Q35: Receipt | S35: -834959 | T35: -795 | U35: SEC-PAY3.1-company | V35: 19-Jun-26 10:16 AM | X35: AAACL0820G | Z35: 7053055928 | AB35: 0 | AD35: EPL | AE35: 5276 | AF35: 7053055928 | AG35: EP00 | AH35: 20260130-SJW10 | AI35: 20260130-SJW10 | AK35: 2025/10 | AM35: ENNOVA | AN35: 30-01-2026 | AO35: 834164 | AP35: INR | AQ35: INR | AR35: 30-01-2026 | AS35: 795199.06 | AT35: 30-01-2026
A36: 274e1989-5f2e-4316-bc94-97976325e7fc | B36: 00367562-24a4-4f8f-80ff-9f982a2591e7 | C36: aa3c61b5-9854-3fe2-9fd7-381cdb7a3021 | D36: TDS Booked by Company | E36: Invoice Number Matched | F36: ledger | G36: 27-11-2025 | H36: ANK2526/GIS00787 | I36: invoice | J36: MF | K36: EMTIG INJECTION [P TO P] | L36: -1691223 | M36: ledger | N36: 27-11-2025 | O36: ANK2526/GIS00787 | P36: invoice | Q36: Sale | S36: 1692835 | T36: 1612 | U36: PRI-INV1.6-company | V36: 19-Jun-26 10:16 AM | X36: AAACL0820G | Z36: 7053053708 | AB36: -1612 | AD36: EPL | AE36: 5906 | AF36: 6006001721 | AG36: EP00 | AH36: ANK2526/GIS00787 | AI36: ANK2526/GIS00787 | AJ36: I3 | AK36: 2025/09 | AL36: EMHC | AM36: CRITI_CARE | AN36: 19-12-2025 | AO36: -1691223 | AP36: INR | AQ36: INR | AR36: 19-12-2025 | AS36: -1612223.8 | AT36: 06-12-2025
A37: 5f10247c-e587-427f-949f-e2e1ffaa410d | B37: 50e3b35b-9047-4be7-af36-0db993f961e8 | C37: c11d5c55-e4a0-3b4f-8aaa-7a1cd55e7744 | D37: TDS Booked by Company | E37: Invoice Number Matched | F37: ledger | G37: 31-07-2025 | H37: ANK2526/SER00044 | I37: invoice | J37: MI | K37: 420005883 SOPRAPEN I.V. 20 MG G | L37: -86526.2 | M37: ledger | N37: 31-07-2025 | O37: ANK2526/SER00044 | P37: invoice | Q37: Other | S37: 88099.2 | T37: 1573 | U37: PRI-INV1.6-company | V37: 19-Jun-26 10:16 AM | X37: AAACL0820G | Z37: 7053030340 | AB37: -1573 | AD37: EPL | AE37: 5159 | AF37: 6008016111 | AG37: EP00 | AH37: ANK2526/SER00044 | AI37: ANK2526/SER00044 | AJ37: IA | AK37: 2025/05 | AL37: ELL2 | AM37: 2500 | AN37: 18-08-2025 | AO37: -86526.2 | AP37: INR | AQ37: INR | AR37: 18-08-2025 | AS37: -78660 | AT37: 26-08-2025
A38: 215b6c63-0821-4a1d-9607-b462e3341c7b | B38: d1d4383f-e165-4af5-886e-e48c124cc044 | C38: c873a8dd-4fbf-3f48-98a8-4474546891b4 | D38: TDS Booked by Company | E38: Invoice Number Matched | F38: ledger | G38: 31-08-2025 | H38: ANK2526/GIS00545 | I38: invoice | J38: MF | K38: MATERNA DEPOT 3.75 MG INJ.[P2P]NSCH-ONCO | L38: -3917289 | M38: ledger | N38: 31-08-2025 | O38: ANK2526/GIS00545 | P38: invoice | Q38: Sale | S38: 3920000 | T38: 2711 | U38: PRI-INV1.6-company | V38: 19-Jun-26 10:16 AM | X38: AAACL0820G | Z38: 7053036126 | AB38: -2711 | AD38: EPL | AE38: 5906 | AF38: 6006001091 | AG38: EP00 | AH38: ANK2526/GIS00545 | AI38: ANK2526/GIS00545 | AJ38: I1 | AK38: 2025/06 | AL38: EMHC | AM38: XENNEA | AN38: 08-09-2025 | AO38: -3917289 | AP38: INR | AQ38: INR | AR38: 08-09-2025 | AS38: -3500000 | AT38: 05-09-2025
A39: 16064676-ddc3-4045-a068-cd796accf406 | B39: 6483bfe6-60a2-48ca-a5d3-f39bda2b6cfb | C39: c8f17e1c-3a7a-39ec-8269-5746cfc5a4f8 | D39: TDS Booked by Party | E39: Date and Amount Matched - Recommended | F39: ledger | G39: 17-06-2025 | H39: 7053012813 | I39: payment | J39: KZ | L39: 1860607 | M39: ledger | N39: 17-06-2025 | O39: AXISCN0994733294 | P39: payment | Q39: Receipt | S39: -1894233.6 | T39: -33626.6 | U39: SEC-PAY3.1-company | V39: 19-Jun-26 10:16 AM | X39: AAACL0820G | Z39: 7053012813 | AB39: 0 | AD39: EPL | AE39: 5159 | AF39: 7053012813 | AG39: EP00 | AH39: 20250617-SJH10 | AI39: 20250617-SJH10 | AK39: 2025/03 | AM39: 2500 | AN39: 17-06-2025 | AO39: 1860607 | AP39: INR | AQ39: INR | AR39: 17-06-2025 | AS39: 1681280 | AT39: 17-06-2025
A40: ee2df619-aa96-4c09-9f21-aa502ad154b7 | B40: ee94a38b-95f5-497b-9848-3949e3dc4007 | C40: cc26e4c9-ecf9-33ca-a270-2d0bb50578bc | D40: TDS Booked by Company | E40: Invoice Number Matched | F40: ledger | G40: 21-08-2025 | H40: ANK2526/SER00050 | I40: invoice | J40: MI | K40: 421111714 MATERNA - HCG 5000 IU | L40: -2460902 | M40: ledger | N40: 21-08-2025 | O40: ANK2526/SER00050 | P40: invoice | Q40: Other | S40: 2505646.1 | T40: 44744.08 | U40: PRI-INV1.6-company | V40: 19-Jun-26 10:16 AM | X40: AAACL0820G | Z40: 7053033678 | AB40: -44744 | AD40: EPL | AE40: 5159 | AF40: 6008017857 | AG40: EP00 | AH40: ANK2526/SER00050 | AI40: ANK2526/SER00050 | AJ40: IA | AK40: 2025/06 | AL40: ELL2 | AM40: 2500 | AN40: 01-09-2025 | AO40: -2460902 | AP40: INR | AQ40: INR | AR40: 01-09-2025 | AS40: -2237184 | AT40: 13-09-2025
...

Sheet 1
A1: Party Id | B1: Matched Id | C1: Status | D1: Classification | E1: Company Statement Type | F1: Company Invoice Date | G1: Company Invoice Number | H1: Company DocType | I1: Company Original DocType | J1: Company Amount | K1: Party Statement Type | L1: Party Invoice Date | M1: Party Invoice Number | N1: Party DocType | O1: Party Original DocType | P1: Party Amount | Q1: Difference | R1: Party Clearing Document Number | S1: Party Clearing Date | T1: Party TDS Amount | U1: Party Posting Date
A2: 59fb819b-d76f-4aef-bd08-7e3dbf42f0c4 | C2: Invoice not booked by Company | D2: Unmatched | J2: 0 | K2: ledger | L2: 27-03-2026 | M2: ANK2526/SER00081 | N2: invoice | O2: Other | P2: 557529 | Q2: 557529

Sheet 10
A1: Company Id | B1: Matched Id | C1: Status | D1: Classification | E1: Company Statement Type | F1: Company Invoice Date | G1: Company Invoice Number | H1: Company DocType | I1: Company Original DocType | J1: Company Amount | K1: Party Statement Type | L1: Party Invoice Date | M1: Party Invoice Number | N1: Party DocType | O1: Party Original DocType | P1: Party Amount | Q1: Difference | R1: Company Clearing Document Number | S1: Company Clearing Date | T1: Company TDS Amount | U1: Company Posting Date
A2: e14afd12-c455-4ae4-be8b-db0b357dbac4 | C2: Invoice not booked by Party | D2: Unmatched | E2: ledger | F2: 27-01-2026 | G2: ANK2526/DBN00012 | H2: invoice | I2: MI | J2: -473280 | P2: 0 | Q2: -473280 | R2: 7053068167 | T2: -8160
A3: 5fb50060-14bd-48e8-9301-272140c55ab4 | C3: Invoice not booked by Party | D3: Unmatched | E3: ledger | F3: 31-07-2025 | G3: ANK2526/DBN00005 | H3: invoice | I3: MI | J3: -254504 | P3: 0 | Q3: -254504 | R3: 7053032930 | T3: -4388
A4: e4d5a91a-46b4-4d2d-9502-565a9e772ded | C4: Invoice not booked by Party | D4: Unmatched | E4: ledger | F4: 10-07-2025 | G4: ANK2526/DNB00003 | H4: invoice | I4: MI | J4: -1555560 | P4: 0 | Q4: -1555560 | R4: 7053038636 | T4: -26820
A5: 073c24a8-8d2a-4cc7-b7f7-698dd4cb4b5a | C5: Invoice not booked by Party | D5: Unmatched | E5: ledger | F5: 27-11-2025 | G5: ANK2526/DBN00008 | H5: invoice | I5: MI | J5: -594152 | P5: 0 | Q5: -594152 | R5: 7053053702 | T5: -10244
A6: b3110aad-4e00-47eb-98b4-53d6f61b7088 | C6: Invoice not booked by Party | D6: Unmatched | E6: ledger | F6: 06-10-2025 | G6: ANK2526/DBN00006 | H6: invoice | I6: MI | J6: -228520 | P6: 0 | Q6: -228520 | R6: 7053052258 | T6: -3940
A7: c259686b-8169-4e00-a872-b4fa7f08123f | C7: Invoice not booked by Party | D7: Unmatched | E7: ledger | F7: 30-04-2025 | G7: ANK2526/DNB00001 | H7: invoice | I7: MI | J7: -14267.66 | P7: 0 | Q7: -14267.66 | R7: 7053015183 | T7: -246

Sheet 23
A1: Party Id | B1: Matched Id | C1: Status | D1: Classification | E1: Company Statement Type | F1: Company Invoice Date | G1: Company Invoice Number | H1: Company DocType | I1: Company Original DocType | J1: Company Amount | K1: Party Statement Type | L1: Party Invoice Date | M1: Party Invoice Number | N1: Party DocType | O1: Party Original DocType | P1: Party Amount | Q1: Difference | R1: Party Clearing Document Number | S1: Party Clearing Date | T1: Party TDS Amount | U1: Party Posting Date
A2: 289ad3fb-1769-409a-909a-3cec95cef9d5 | C2: Credit Note not booked by Company | D2: Unmatched | J2: 0 | K2: ledger | L2: 10-07-2025 | M2: DNB00011 | N2: creditNote | O2: CN | P2: 1582380 | Q2: 1582380
A3: 51e03a91-560b-460b-b310-15e4b684e22e | C3: Credit Note not booked by Company | D3: Unmatched | J3: 0 | K3: ledger | L3: 31-07-2025 | M3: ANK2526/DBN00005 | N3: creditNote | O3: CN | P3: 258892 | Q3: 258892
A4: 5f77d353-a5e7-40cc-a460-0d1a90be31dc | C4: Credit Note not booked by Company | D4: Unmatched | J4: 0 | K4: ledger | L4: 27-11-2025 | M4: ANK2526/DBN00008 | N4: creditNote | O4: CN | P4: 604396 | Q4: 604396
A5: 7fd61a63-5c6f-4418-8e12-d7b417b9492a | C5: Credit Note not booked by Company | D5: Unmatched | J5: 0 | K5: ledger | L5: 20-02-2026 | M5: ANK2526/DBN00015 | N5: creditNote | O5: CN | P5: 388928 | Q5: 388928
A6: 0ca58a7f-65da-4e3e-a0ec-1d98d9e3a5f4 | C6: Credit Note not booked by Company | D6: Unmatched | J6: 0 | K6: ledger | L6: 14-03-2026 | M6: ANK2526/DBN00016 | N6: creditNote | O6: CN | P6: 283200 | Q6: 283200
A7: 71edf8a4-9888-4518-bcac-ae43e5ea8193 | C7: Credit Note not booked by Company | D7: Unmatched | J7: 0 | K7: ledger | L7: 06-10-2025 | M7: ANK2526/DBN00006 | N7: creditNote | O7: CN | P7: 232460 | Q7: 232460
A8: e13ee45f-1714-42a1-8a12-427f9993b620 | C8: Credit Note not booked by Company | D8: Unmatched | J8: 0 | K8: ledger | L8: 13-12-2025 | M8: ANK2526/DBN00009 | N8: creditNote | O8: CN | P8: 215822 | Q8: 215822
A9: 2b2ced9b-b480-4be7-a59a-1a5ae8f5bc89 | C9: Credit Note not booked by Company | D9: Unmatched | J9: 0 | K9: ledger | L9: 27-01-2026 | M9: ANK2526/DBN00012 | N9: creditNote | O9: CN | P9: 481440 | Q9: 481440

Sheet 55
A1: Party Id | B1: Matched Id | C1: Status | D1: Classification | E1: Company Statement Type | F1: Company Invoice Date | G1: Company Invoice Number | H1: Company DocType | I1: Company Original DocType | J1: Company Amount | K1: Party Statement Type | L1: Party Invoice Date | M1: Party Invoice Number | N1: Party DocType | O1: Party Original DocType | P1: Party Amount | Q1: Difference | R1: Party Clearing Document Number | S1: Party Clearing Date | T1: Party TDS Amount | U1: Party Posting Date
A2: 699bd5e5-b0b1-4afe-8de7-ca8f3322ccdd | C2: Payment not booked by Company | D2: Unmatched | J2: 0 | K2: ledger | L2: 27-05-2025 | M2: AXISCN0981979347 | N2: payment | O2: Receipt | P2: -1814400 | Q2: -1814400
A3: a9c1ac6e-0179-4c48-aa04-92b6534f0220 | C3: Payment not booked by Company | D3: Unmatched | J3: 0 | K3: ledger | L3: 11-04-2025 | M3: UTIBN62025041155260266 | N3: payment | O3: Receipt | P3: -743400 | Q3: -743400
A4: 7c6c5123-ba1b-483a-b795-ac9d11e632ab | C4: Payment not booked by Company | D4: Unmatched | J4: 0 | K4: ledger | L4: 13-05-2025 | M4: UTIBN62025051387607677 | N4: payment | O4: Receipt | P4: -914457.6 | Q4: -914457.6
A5: b7683659-9606-4d14-a006-f256e3cdadab | C5: Payment not booked by Company | D5: Unmatched | J5: 0 | K5: ledger | L5: 11-04-2025 | M5: UTIBN62025041155258988 | N5: payment | O5: Receipt | P5: -938407.68 | Q5: -938407.68

Sheet 61
A1: Company Id | B1: Matched Id | C1: Status | D1: Classification | E1: Company Statement Type | F1: Company Invoice Date | G1: Company Invoice Number | H1: Company DocType | I1: Company Original DocType | J1: Company Amount | K1: Party Statement Type | L1: Party Invoice Date | M1: Party Invoice Number | N1: Party DocType | O1: Party Original DocType | P1: Party Amount | Q1: Difference | R1: Company Clearing Document Number | S1: Company Clearing Date | T1: Company TDS Amount | U1: Company Posting Date
A2: 8a49aa96-c2ab-4471-89a5-2a3188aa2216 | C2: Payment not booked by Party | D2: Unmatched | E2: ledger | F2: 29-05-2025 | G2: 7053009822 | H2: payment | I2: KZ | J2: 1784336 | P2: 0 | Q2: 1784336 | R2: 7053009822 | T2: 0
A3: f34a070e-e679-4049-80b8-68848063d92e | C3: Payment not booked by Party | D3: Unmatched | E3: ledger | F3: 08-04-2025 | G3: 7053001045 | H3: payment | I3: KZ | J3: 921650 | P3: 0 | Q3: 921650 | R3: 7053001045 | T3: 0
A4: d33cdc7d-5f77-4869-8028-863e1c13fa15 | C4: Payment not booked by Party | D4: Unmatched | E4: ledger | F4: 14-01-2026 | G4: 7053052258 | H4: payment | I4: KZ | J4: 228520 | P4: 0 | Q4: 228520 | R4: 7053052258 | T4: 0
A5: 39dbb1dc-74fc-4a82-81c0-d022eb6cf108 | C5: Payment not booked by Party | D5: Unmatched | E5: ledger | F5: 08-04-2025 | G5: 7053001046 | H5: payment | I5: KZ | J5: 730800 | P5: 0 | Q5: 730800 | R5: 7053001046 | T5: 0
A6: 3da2bcee-2cbd-4a91-8f1f-7fd7fbf27f05 | C6: Payment not booked by Party | D6: Unmatched | E6: ledger | F6: 31-03-2026 | G6: 7053068167 | H6: payment | I6: KZ | J6: 473280 | P6: 0 | Q6: 473280 | R6: 7053068167 | T6: 0
A7: 484c0899-5552-42fe-a29f-e62c7cb48391 | C7: Payment not booked by Party | D7: Unmatched | E7: ledger | F7: 29-05-2025 | G7: 7053009823 | H7: payment | I7: KZ | J7: 613.96 | P7: 0 | Q7: 613.96 | R7: 7053009823 | T7: 0
A8: 74d9080b-e369-46b4-9ccb-72f40b32f1a5 | C8: Payment not booked by Party | D8: Unmatched | E8: ledger | F8: 12-05-2025 | G8: 7053006480 | H8: payment | I8: KZ | J8: 898127 | P8: 0 | Q8: 898127 | R8: 7053006480 | T8: 0

Sheet 74
A1: Party Id | B1: Matched Id | C1: Status | D1: Classification | E1: Company Statement Type | F1: Company Invoice Date | G1: Company Invoice Number | H1: Company DocType | I1: Company Original DocType | J1: Company Amount | K1: Party Statement Type | L1: Party Invoice Date | M1: Party Invoice Number | N1: Party DocType | O1: Party Original DocType | P1: Party Amount | Q1: Difference | R1: Party Clearing Document Number | S1: Party Clearing Date | T1: Party TDS Amount | U1: Party Posting Date
A2: 647bee11-a5ff-4a23-870f-f583d6cf62b8 | C2: Other entry not booked by Company | D2: Unmatched | J2: 0 | K2: ledger | L2: 30-09-2025 | M2: DEBTORS WRITE OFF | N2: journal | O2: Journal | P2: 25440 | Q2: 25440

Sheet 79
A1: Company Id | B1: Matched Id | C1: Status | D1: Classification | E1: Company Statement Type | F1: Company Invoice Date | G1: Company Invoice Number | H1: Company DocType | I1: Company Original DocType | J1: Company Amount | K1: Party Statement Type | L1: Party Invoice Date | M1: Party Invoice Number | N1: Party DocType | O1: Party Original DocType | P1: Party Amount | Q1: Difference | R1: Company Clearing Document Number | S1: Company Clearing Date | T1: Company TDS Amount | U1: Company Posting Date
A2: 66848aa3-8721-45f9-8f07-7fcdafb4f510 | C2: Other entry not booked by Party | D2: Unmatched | E2: ledger | F2: 31-03-2026 | H2: journal | I2: SA | J2: -179242 | P2: 0 | Q2: -179242 | R2: 7001002085 | T2: -3658
A3: da1f6ac3-73fd-4107-8171-cf14d6b7bbb0 | C3: Other entry not booked by Party | D3: Unmatched | E3: ledger | F3: 31-03-2026 | H3: journal | I3: SA | J3: -235200 | P3: 0 | Q3: -235200 | R3: 7001002096 | T3: -4800
A4: a394fbd0-1313-4234-b850-d30ff082d74b | C4: Other entry not booked by Party | D4: Unmatched | E4: ledger | F4: 31-03-2026 | H4: journal | I4: SA | J4: -520360 | P4: 0 | Q4: -520360 | R4: 7001008009 | T4: -10620

Sheet 94
A1: Company Id | B1: Party Id | C1: Matched Id | D1: Status | E1: Classification | F1: Company Statement Type | G1: Company Invoice Date | H1: Company Invoice Number | I1: Company DocType | J1: Company Original DocType | K1: Company Narration | L1: Company Amount | M1: Party Statement Type | N1: Party Invoice Date | O1: Party Invoice Number | P1: Party DocType | Q1: Party Original DocType | R1: Party Narration | S1: Party Amount | T1: Difference
A2: 274e1989-5f2e-4316-bc94-97976325e7fc | B2: 00367562-24a4-4f8f-80ff-9f982a2591e7 | C2: aa3c61b5-9854-3fe2-9fd7-381cdb7a3021 | D2: TDS Booked by Company | E2: Invoice Number Matched | F2: ledger | G2: 27-11-2025 | H2: ANK2526/GIS00787 | I2: invoice | J2: MF | K2: EMTIG INJECTION [P TO P] | L2: -1691223 | M2: ledger | N2: 27-11-2025 | O2: ANK2526/GIS00787 | P2: invoice | Q2: Sale | S2: 1692835 | T2: 1612
A3: 4496d1c4-1e8a-4d2d-968c-d797ac14155c | B3: 03c26d9f-6c72-4e5f-bfec-675ae5dc3ecd | C3: 2399b5aa-899a-3e44-8e5f-4d09a538a2c3 | D3: TDS Booked by Company | E3: Invoice Number Matched | F3: ledger | G3: 21-04-2025 | H3: ANK2526/SER00001 | I3: invoice | J3: MI | K3: 421111714 MATERNA - HCG 5000 IU | L3: -1860607 | M3: ledger | N3: 21-04-2025 | O3: ANK2526/SER00001 | P3: invoice | Q3: Other | S3: 1894233.6 | T3: 33626.6
A4: 450bd921-1a8d-4845-b2ae-bf1216fd9198 | B4: 2eff2df9-aac2-4397-a9c7-638e6ac9253a | C4: 2a78bd4d-795a-39e0-b2e2-25d82ab37a71 | D4: TDS Booked by Company | E4: Invoice Number Matched | F4: ledger | G4: 16-03-2026 | H4: ANK2526/SER00080 | I4: invoice | J4: MI | K4: 421111716 MATERNA - HMG 75 IU | L4: -1372125 | M4: ledger | N4: 16-03-2026 | O4: ANK2526/SER00080 | P4: invoice | Q4: Other | S4: 1398768 | T4: 26643
A5: 19cf0320-a7d6-4632-93f9-3aa8ebabefda | B5: 356677a1-0763-4f5f-b67d-9fa67464a66e | C5: 33b8f008-c93f-3a19-a5a5-37851b94ef77 | D5: TDS Booked by Company | E5: Invoice Number Matched | F5: ledger | G5: 10-12-2025 | H5: ANK2526/GIS00839 | I5: invoice | J5: MF | K5: REBEZ IV INJECTION [P TO P] | L5: -1666450 | M5: ledger | N5: 10-12-2025 | O5: ANK2526/GIS00839 | P5: invoice | Q5: Sale | S5: 1668039 | T5: 1589
A6: 70d5264b-d33f-4983-93dd-ef6ff1535b45 | B6: 363f9169-6096-452e-9b08-14f89e80ab75 | C6: 96ca066f-f3dd-31d1-8565-a73b4c76be09 | D6: TDS Booked by Company | E6: Invoice Number Matched | F6: ledger | G6: 02-08-2025 | H6: ANK2526/SER00045 | I6: invoice | J6: MI | K6: Job Work Charge - AUG 2025 | L6: -1227.92 | M6: ledger | N6: 02-08-2025 | O6: ANK2526/SER00045 | P6: invoice | Q6: Other | S6: 1249.92 | T6: 22
A7: 1bdafe07-41ec-47b3-baed-36acb746303a | B7: 3c3607e3-b64d-4e2d-8c7c-98b4f01adbac | C7: 252dae23-d549-3aa6-a82d-35d32098b55f | D7: TDS Booked by Company | E7: Invoice Number Matched | F7: ledger | G7: 29-01-2026 | H7: ANK2526/GIS00934 | I7: invoice | J7: MF | K7: REBEZ IV INJECTION [P TO P] | L7: -1370813 | M7: ledger | N7: 29-01-2026 | O7: ANK2526/GIS00934 | P7: invoice | Q7: Sale | S7: 1372120 | T7: 1307
A8: e88999b1-05ec-4268-bbbc-5119f6a8b867 | B8: 3df3999c-3eae-447e-86eb-ace45ffe1656 | C8: 7969e88d-93c3-3ac6-a71b-a5a023490392 | D8: TDS Booked by Company | E8: Invoice Number Matched | F8: ledger | G8: 31-10-2025 | H8: ANK2526/GIS00697 | I8: invoice | J8: MF | K8: EMTIG INJECTION [P TO P] | L8: -3480330 | M8: ledger | N8: 31-10-2025 | O8: ANK2526/GIS00697 | P8: invoice | Q8: Sale | S8: 3483648 | T8: 3318
A9: 40a85208-dcf4-496e-bfaa-a1aa50d87efd | B9: 412b0cf1-2b9a-4f3d-b552-fb96018b8efd | C9: 5e3d74eb-1238-31a5-b9ea-68850a0ee4b8 | D9: TDS Booked by Company | E9: Invoice Number Matched | F9: ledger | G9: 21-08-2025 | H9: ANK2526/SER00049 | I9: invoice | J9: KR | K9: LYKA RATE DIFFERENCE | L9: -99742 | M9: ledger | N9: 21-08-2025 | O9: ANK2526/SER00049 | P9: invoice | Q9: Other | S9: 101556 | T9: 1814
A10: 168a257c-6f08-46b6-9608-0725e376ecba | B10: 4cabb64d-c453-46f4-808e-9156760af86e | C10: 5a843abf-e9ca-324c-afd1-0dedba4227f0 | D10: TDS Booked by Company | E10: Invoice Number Matched | F10: ledger | G10: 26-11-2025 | H10: ANK2526/GIS00781 | I10: invoice | J10: MF | K10: REBEZ IV INJECTION [P TO P] | L10: -292718 | M10: ledger | N10: 26-11-2025 | O10: ANK2526/GIS00781 | P10: invoice | Q10: Sale | S10: 292997 | T10: 279
A11: 5f10247c-e587-427f-949f-e2e1ffaa410d | B11: 50e3b35b-9047-4be7-af36-0db993f961e8 | C11: c11d5c55-e4a0-3b4f-8aaa-7a1cd55e7744 | D11: TDS Booked by Company | E11: Invoice Number Matched | F11: ledger | G11: 31-07-2025 | H11: ANK2526/SER00044 | I11: invoice | J11: MI | K11: 420005883 SOPRAPEN I.V. 20 MG G | L11: -86526.2 | M11: ledger | N11: 31-07-2025 | O11: ANK2526/SER00044 | P11: invoice | Q11: Other | S11: 88099.2 | T11: 1573
A12: 5d4248ec-7a4e-4fcd-bcc9-3fa3cbd79825 | B12: 80f49ab0-4efa-4eda-b1aa-723f9a2e2702 | C12: 7515671b-9a76-3276-8caa-36e894b60403 | D12: TDS Booked by Company | E12: Invoice Number Matched | F12: ledger | G12: 30-11-2025 | H12: ANK2526/GIS00823 | I12: invoice | J12: MF | K12: REBEZ IV INJECTION [P TO P] | L12: -834164 | M12: ledger | N12: 30-11-2025 | O12: ANK2526/GIS00823 | P12: invoice | Q12: Sale | S12: 834959 | T12: 795
A13: 31bbc752-4579-4f0a-8c60-93d9f4763baa | B13: 81bba397-4096-40c8-b7e2-b7017396a2d5 | C13: 4121dcea-21e1-39ea-b2ae-617ac8d404e6 | D13: TDS Booked by Company | E13: Invoice Number Matched | F13: ledger | G13: 27-11-2025 | H13: ANK2526/GIS00786 | I13: invoice | J13: MF | K13: EMTIG INJECTION [P TO P] | L13: -1707537 | M13: ledger | N13: 27-11-2025 | O13: ANK2526/GIS00786 | P13: invoice | Q13: Sale | S13: 1709165 | T13: 1628
... A22: feffc451-9eb3-4171-8faf-000859405a38 | B22: fad17af0-baf0-4352-a9e7-25d790de30fe | C22: 80ae845c-e9fa-33be-bd86-890140fe421e | D22: TDS Booked by Company | E22: Invoice Number Matched | F22: ledger | G22: 26-11-2025 | H22: ANK2526/GIS00782 | I22: invoice | J22: MF | K22: REBEZ IV INJECTION [P TO P] | L22: -120715 | M22: ledger | N22: 26-11-2025 | O22: ANK2526/GIS00782 | P22: invoice | Q22: Sale | S22: 120830 | T22: 115
A23: 524bc8e0-a4a8-42e8-b23d-c1f23686de5a | B23: 186ecf5a-6b8f-46dc-affc-8da4ff6898d7 | C23: 23202ed6-9dcb-4c15-beab-145bc4a547de | D23: TDS Booked by Party | E23: Payment Matched - Recommended | F23: ledger | G23: 22-01-2026 | H23: 7053054141 | I23: payment | J23: KZ | L23: 413433 | M23: ledger | N23: 23-01-2026 | O23: UTIBR72026012300040395 | P23: payment | Q23: Receipt | S23: -413827 | T23: -394
A24: 01b0bfca-76c7-41e4-b373-b8f58d7c5a86 | B24: 1e1bce79-95dd-4cc6-8b1b-ff4d93cc6372 | C24: 4d6f23b7-dd76-3d73-b15f-1e43a867c178 | D24: TDS Booked by Party | E24: Date and Amount Matched - Recommended | F24: ledger | G24: 17-04-2025 | H24: 7053002545 | I24: payment | J24: KZ | L24: 7298494 | M24: ledger | N24: 17-04-2025 | O24: UTIBR72025041700038257 | P24: payment | Q24: Receipt | S24: -7305016 | T24: -6522
A25: 06b4cbc1-df7c-4dc2-a5e5-e3ed11468e91 | B25: 45a5cece-d771-4b25-a062-d0c539fffa26 | C25: 1395c5ae-873f-3f8b-ae53-ab71616636e5 | D25: TDS Booked by Party | E25: Multiple Based on Date | F25: ledger | G25: 08-10-2025 | H25: 7053032927 | I25: payment | J25: KZ | L25: 99742 | M25: ledger | N25: 08-10-2025 | O25: UTIBR72025100800060307 | P25: payment | Q25: Receipt | S25: 0 | T25: 0
A26: c9413937-a0a2-440e-afed-243116b6bb39 | B26: c0ac7d01-7b9c-40c6-abca-c0fdf6d3a1c1 | C26: 1395c5ae-873f-3f8b-ae53-ab71616636e5 | D26: TDS Booked by Party | E26: Multiple Based on Date | F26: ledger | G26: 08-10-2025 | H26: 7053033057 | I26: payment | J26: KZ | L26: 817740 | M26: ledger | N26: 08-10-2025 | O26: AXISCN1112025593 | P26: payment | Q26: Receipt | S26: 0 | T26: 0
A27: 77c42784-11ca-4039-a04e-9fc050e211d9 | B27: e052f7df-7a34-409c-820d-426b4b035581 | C27: 1395c5ae-873f-3f8b-ae53-ab71616636e5 | D27: TDS Booked by Party | E27: Multiple Based on Date | F27: ledger | G27: 08-10-2025 | H27: 7053032930 | I27: payment | J27: KZ | L27: 257573.8 | M27: ledger | N27: 08-10-2025 | O27: AXISCN1112157656 | P27: payment | Q27: Receipt | S27: -1178188 | T27: -3132.2
A28: a0968703-cc23-44af-b031-f718ce9e84ce | B28: 4b5709cd-1408-4b7e-8e81-53c786fe9b81 | C28: e817c417-e8ce-344a-9cf1-b855d2c82a41 | D28: TDS Booked by Party | E28: Date and Amount Matched - Recommended | F28: ledger | G28: 01-07-2025 | H28: 7053015183 | I28: payment | J28: KZ | L28: 14267.66 | M28: ledger | N28: 01-07-2025 | O28: AXISCN1007743339 | P28: payment | Q28: Receipt | S28: -14514 | T28: -246.34
A29: e3064d9b-36d2-47c3-b614-7a93582dac31 | B29: 4bf4f1e8-4ea0-4ebd-a461-51858d4a1d59 | C29: 05f4488d-878f-3ab2-a045-a82fee6d3bcb | D29: TDS Booked by Party | E29: Date and Amount Matched - Recommended | F29: ledger | G29: 16-05-2025 | H29: 7053007500 | I29: payment | J29: KZ | L29: 1359585 | M29: ledger | N29: 16-05-2025 | O29: UTIBN62025051618331475 | P29: payment | Q29: Receipt | S29: -1360800 | T29: -1215
A30: eb499910-3892-42be-97e6-0ca5eb6ab8ee | B30: 51022052-eebc-4fbc-a428-096361b8a8c3 | C30: d770e8f0-576e-355f-b490-2555388f5d28 | D30: TDS Booked by Party | E30: Date and Amount Matched - Recommended | F30: ledger | G30: 06-11-2025 | H30: 7053038636 | I30: payment | J30: KZ | L30: 1555560 | M30: ledger | N30: 06-11-2025 | O30: UTIBR72025110600053262 | P30: payment | Q30: Receipt | S30: -1582380 | T30: -26820
A31: ffb7e322-b11e-418d-8624-0c78428ff4bc | B31: 5ce800c0-06e5-4125-a988-a782f27d2933 | C31: 30c02a2c-73e5-4135-843c-26b6c22ef8ec | D31: TDS Booked by Party | E31: Multiple Based on Invoice Number and Date Range | F31: ledger | G31: 26-05-2025 | H31: 7053009079 | I31: payment | J31: KZ | L31: 1812780 | M31: ledger | N31: 30-05-2025 | O31: AXISCN0983739554 | P31: payment | Q31: Receipt | S31: -1817403.8 | T31: -4623.84
A32: 16064676-ddc3-4045-a068-cd796accf406 | B32: 6483bfe6-60a2-48ca-a5d3-f39bda2b6cfb | C32: c8f17e1c-3a7a-39ec-8269-5746cfc5a4f8 | D32: TDS Booked by Party | E32: Date and Amount Matched - Recommended | F32: ledger | G32: 17-06-2025 | H32: 7053012813 | I32: payment | J32: KZ | L32: 1860607 | M32: ledger | N32: 17-06-2025 | O32: AXISCN0994733294 | P32: payment | Q32: Receipt | S32: -1894233.6 | T32: -33626.6
A33: 7c3db2b5-709b-419a-9fee-1ff7747aea8a | B33: 6a61b6ee-0eba-480f-ba9a-db85633f5e91 | C33: 5c4816a8-ac14-3e72-9090-a3b72bad22e7 | D33: TDS Booked by Party | E33: Date and Amount Matched - Recommended | F33: ledger | G33: 01-10-2025 | H33: 7053031634 | I33: payment | J33: KZ | L33: 1070387 | M33: ledger | N33: 01-10-2025 | O33: AXISCN1103265077 | P33: payment | Q33: Receipt | S33: -1089849.6 | T33: -19462.6
A34: 823a6688-4523-4a8e-9948-a9933e848717 | B34: 8c1a1eab-34db-4f50-8dd1-f0029d456470 | C34: 272317a6-3e17-325e-9f62-8625bbbb07c3 | D34: TDS Booked by Party | E34: Multiple Based on Date | F34: ledger | G34: 21-01-2026 | H34: 7053053702 | I34: payment | J34: KZ | L34: 594152 | M34: ledger | N34: 21-01-2026 | O34: UTIBR72026012100004817 | P34: payment | Q34: Receipt | S34: 0 | T34: 0
... A42: b2e347ad-12a7-49e8-b77b-8588201eb191 | B42: f8ecbfc7-0224-4122-8ad2-06231f412d43 | C42: e2732d49-1980-36ce-9173-91c7827c949c | D42: TDS Booked by Party | E42: Date and Amount Matched - Recommended | F42: ledger | G42: 21-05-2025 | H42: 7053008353 | I42: payment | J42: KZ | L42: 1066852 | M42: ledger | N42: 21-05-2025 | O42: AXISCN0979676342 | P42: payment | Q42: Receipt | S42: -1085246 | T42: -18394
B43: 54c64096-ea61-4f44-9146-bd38fc6090d0 | D43: TDS Booked by Party | E43: TDS Booked by Party | L43: 0 | M43: ledger | N43: 31-03-2026 | O43: TDS ANK2526/GIS00926 | P43: tds | Q43: TDS | S43: -1537 | T43: -1537
B44: b9dcae01-168d-49d8-a84f-53ecc4177168 | D44: TDS Booked by Party | E44: TDS Booked by Party | L44: 0 | M44: ledger | N44: 31-03-2026 | O44: TDS ANK2526/GIS00923 | P44: tds | Q44: TDS | S44: -3262.46 | T44: -3262.46
B45: df1331d7-652e-411d-9518-195aafb24082 | D45: TDS Booked by Party | E45: TDS Booked by Party | L45: 0 | M45: ledger | N45: 31-03-2026 | O45: TDS DEDUCTED | P45: tds | Q45: TDS | S45: -8458 | T45: -8458
B46: 9870be35-0fc7-442d-866b-dec7a75ddd57 | D46: TDS Booked by Party | E46: TDS Booked by Party | L46: 0 | M46: ledger | N46: 31-03-2026 | O46: TDS ANK2526/GIS00934 | P46: tds | Q46: TDS | S46: -1307 | T46: -1307

Sheet Party
