Workbook

Sheet Summary
A1: Party Name | B1: INOX AIR PRODUCTS PRIVATE LIMITED | C1: Date Tolerance | D1: 0 - 15
A2: Reconciliation Period | B2: 01-Apr-2025 to 31-Mar-2026 | C2: TDS Percentage | D2: 0.0 - 10.0
A3: Statement Type | B3: Ledger | C3: Amount Tolerance | D3: 1.0 Rs
A4: Party Type | B4: Vendor
A5: Reconciliation Date | B5: 03-Aug-26 04:10 PM
A7: Reconciliation Statement
A8: Particulars | B8: Annexure | C8: Amount | D8: No. of Entries | E8: Action Required
A9: Closing Balance Difference | C9: =SUM(C10:C11) -> 64448.34 | D9: =SUM(D10:D11) -> 2
A10: Closing Balance as per Company | C10: =-(SUMIFS(Reconciliation!L:L,Reconciliation!D:D,A10,Reconciliation!F:F,"ledger") +SUMIFS(Reconciliation!S:S,Reconciliation!D:D,A10,Reconciliation!M:M,"ledger")) -> -152786.08 | D10: =COUNTIFS(Reconciliation!D:D,A10,Reconciliation!F:F,"ledger") +COUNTIFS(Reconciliation!D:D,A10,Reconciliation!M:M,"ledger") -> 1
A11: Closing Balance as per Party | C11: =-(SUMIFS(Reconciliation!L:L,Reconciliation!D:D,A11,Reconciliation!F:F,"ledger") +SUMIFS(Reconciliation!S:S,Reconciliation!D:D,A11,Reconciliation!M:M,"ledger")) -> 217234.42 | D11: =COUNTIFS(Reconciliation!D:D,A11,Reconciliation!F:F,"ledger") +COUNTIFS(Reconciliation!D:D,A11,Reconciliation!M:M,"ledger") -> 1
A13: Invoice Difference | C13: =SUM(C14:C14) -> 204357.32 | D13: =SUM(D14:D14) -> 3
A14: Invoice not booked by Company | B14: 1 | C14: =SUMIFS(Reconciliation!L:L,Reconciliation!D:D,A14,Reconciliation!F:F,"ledger") +SUMIFS(Reconciliation!S:S,Reconciliation!D:D,A14,Reconciliation!M:M,"ledger") -> 204357.32 | D14: =COUNTIFS(Reconciliation!D:D,A14,Reconciliation!F:F,"ledger") +COUNTIFS(Reconciliation!D:D,A14,Reconciliation!M:M,"ledger") -> 3 | E14: Vendor to provide the invoice copies
A15: Debit Note / Credit Note Difference | C15: =SUM(C16:C16) -> 17174.51 | D15: =SUM(D16:D16) -> 1
A16: Debit Note not booked by Party | B16: 33 | C16: =SUMIFS(Reconciliation!L:L,Reconciliation!D:D,A16,Reconciliation!F:F,"ledger") +SUMIFS(Reconciliation!S:S,Reconciliation!D:D,A16,Reconciliation!M:M,"ledger") -> 17174.51 | D16: =COUNTIFS(Reconciliation!D:D,A16,Reconciliation!F:F,"ledger") +COUNTIFS(Reconciliation!D:D,A16,Reconciliation!M:M,"ledger") -> 1 | E16: Vendor to book the Credit Note for Shortage / Deduction / Rate Difference etc
A17: Other Differences | C17: =SUM(C18:C19) -> -23983.59 | D17: =SUM(D18:D19) -> 29
A18: Other entry not booked by Company | B18: 74 | C18: =SUMIFS(Reconciliation!L:L,Reconciliation!D:D,A18,Reconciliation!F:F,"ledger") +SUMIFS(Reconciliation!S:S,Reconciliation!D:D,A18,Reconciliation!M:M,"ledger") -> -6809.08 | D18: =COUNTIFS(Reconciliation!D:D,A18,Reconciliation!F:F,"ledger") +COUNTIFS(Reconciliation!D:D,A18,Reconciliation!M:M,"ledger") -> 28
A19: Other entry not booked by Party | B19: 79 | C19: =SUMIFS(Reconciliation!L:L,Reconciliation!D:D,A19,Reconciliation!F:F,"ledger") +SUMIFS(Reconciliation!S:S,Reconciliation!D:D,A19,Reconciliation!M:M,"ledger") -> -17174.51 | D19: =COUNTIFS(Reconciliation!D:D,A19,Reconciliation!F:F,"ledger") +COUNTIFS(Reconciliation!D:D,A19,Reconciliation!M:M,"ledger") -> 1
A20: TDS / TCS Difference | C20: =SUM(C21:C22) -> 6799.99 | D20: =SUM(D21:D22) -> 15
A21: TDS Booked by Company | B21: 94 | C21: =SUMIFS(Reconciliation!T:T,Reconciliation!D:D,A21) -SUMIFS(Reconciliation!T:T,Reconciliation!D:D,A21,Reconciliation!F:F,"Brought forward",Reconciliation!M:M,"Brought forward") -SUMIFS(Reconciliation!T:T,Reconciliation!D:D,A21,Reconciliation!F:F,"Brought forward",Reconciliation!I:I,"tds") -SUMIFS(Reconciliation!T:T,Reconciliation!D:D,A21,Reconciliation!M:M,"Brought forward",Reconciliation!P:P,"tds") -> 7800 | D21: =COUNTIFS(Reconciliation!D:D,A21) -COUNTIFS(Reconciliation!D:D,A21,Reconciliation!F:F,"Brought forward",Reconciliation!M:M,"Brought forward") -COUNTIFS(Reconciliation!D:D,A21,Reconciliation!F:F,"Brought forward",Reconciliation!I:I,"tds") -COUNTIFS(Reconciliation!D:D,A21,Reconciliation!M:M,"Brought forward",Reconciliation!P:P,"tds") -> 14 | E21: Vendor to book the TDS entries
A22: TDS Booked by Party | B22: 94 | C22: =SUMIFS(Reconciliation!T:T,Reconciliation!D:D,A22) -SUMIFS(Reconciliation!T:T,Reconciliation!D:D,A22,Reconciliation!F:F,"Brought forward",Reconciliation!M:M,"Brought forward") -SUMIFS(Reconciliation!T:T,Reconciliation!D:D,A22,Reconciliation!F:F,"Brought forward",Reconciliation!I:I,"tds") -SUMIFS(Reconciliation!T:T,Reconciliation!D:D,A22,Reconciliation!M:M,"Brought forward",Reconciliation!P:P,"tds") -> -1000.01 | D22: =COUNTIFS(Reconciliation!D:D,A22) -COUNTIFS(Reconciliation!D:D,A22,Reconciliation!F:F,"Brought forward",Reconciliation!M:M,"Brought forward") -COUNTIFS(Reconciliation!D:D,A22,Reconciliation!F:F,"Brought forward",Reconciliation!I:I,"tds") -COUNTIFS(Reconciliation!D:D,A22,Reconciliation!M:M,"Brought forward",Reconciliation!P:P,"tds") -> 1 | E22: Vendor to book the TDS entries
A23: Write Off / Rounding Off | C23: =SUM(C24:C24) -> 23.17 | D23: =SUM(D24:D24) -> 63
A24: Write off / Rounding off | C24: =SUMIFS(Reconciliation!T:T,Reconciliation!D:D,A24) -SUMIFS(Reconciliation!T:T,Reconciliation!D:D,A24,Reconciliation!F:F,"Brought forward",Reconciliation!M:M,"Brought forward") -SUMIFS(Reconciliation!T:T,Reconciliation!D:D,A24,Reconciliation!F:F,"Brought forward",Reconciliation!I:I,"tds") -SUMIFS(Reconciliation!T:T,Reconciliation!D:D,A24,Reconciliation!M:M,"Brought forward",Reconciliation!P:P,"tds") -> 23.17 | D24: =COUNTIFS(Reconciliation!D:D,A24) -COUNTIFS(Reconciliation!D:D,A24,Reconciliation!F:F,"Brought forward",Reconciliation!M:M,"Brought forward") -COUNTIFS(Reconciliation!D:D,A24,Reconciliation!F:F,"Brought forward",Reconciliation!I:I,"tds") -COUNTIFS(Reconciliation!D:D,A24,Reconciliation!M:M,"Brought forward",Reconciliation!P:P,"tds") -> 63 | E24: No Action Required
A25: Reversal Entries | C25: =SUM(C26:C26) -> -18.34 | D25: =SUM(D26:D26) -> 208
A26: Reversal Entries | C26: =SUMIFS(Reconciliation!L:L,Reconciliation!D:D,A26,Reconciliation!F:F,"ledger") +SUMIFS(Reconciliation!S:S,Reconciliation!D:D,A26,Reconciliation!M:M,"ledger") -> -18.34 | D26: =COUNTIFS(Reconciliation!D:D,A26,Reconciliation!F:F,"ledger") +COUNTIFS(Reconciliation!D:D,A26,Reconciliation!M:M,"ledger") -> 208 | E26: No Action Required
A27: Opening Balance Difference | C27: =SUM(C28:C31) -> -139904.72 | D27: =SUM(D28:D31) -> 3
A28: Opening Balance as per Company | C28: =SUMIFS(Reconciliation!L:L,Reconciliation!D:D,A28,Reconciliation!F:F,"ledger") +SUMIFS(Reconciliation!S:S,Reconciliation!D:D,A28,Reconciliation!M:M,"ledger") -> -139904.72 | D28: =COUNTIFS(Reconciliation!D:D,A28,Reconciliation!F:F,"ledger") +COUNTIFS(Reconciliation!D:D,A28,Reconciliation!M:M,"ledger") -> 2
A29: Opening Balance as per Party | C29: =SUMIFS(Reconciliation!L:L,Reconciliation!D:D,A29,Reconciliation!F:F,"ledger") +SUMIFS(Reconciliation!S:S,Reconciliation!D:D,A29,Reconciliation!M:M,"ledger") -> 0 | D29: =COUNTIFS(Reconciliation!D:D,A29,Reconciliation!F:F,"ledger") +COUNTIFS(Reconciliation!D:D,A29,Reconciliation!M:M,"ledger") -> 1 | E29: Vendor to provide the breakup of Opening Balance
A30: Brought forward entries matched - company | B30: 210 | C30: 0 | D30: 0
A31: Brought forward entries matched - party | B31: 211 | C31: 0 | D31: 0
A32: Calculated Balance | C32: =C13+C15+C17+C20+C23+C25+C27 -> 64448.34
A34: Difference | C34: =C9-C32 -> 0

Sheet Reconciliation
A1: Company Id | B1: Party Id | C1: Matched Id | D1: Status | E1: Classification | F1: Company Statement Type | G1: Company Invoice Date | H1: Company Invoice Number | I1: Company DocType | J1: Company Original DocType | K1: Company Narration | L1: Company Amount | M1: Party Statement Type | N1: Party Invoice Date | O1: Party Invoice Number | P1: Party DocType | Q1: Party Original DocType | R1: Party Narration | S1: Party Amount | T1: Difference | U1: Matched Rule | V1: Reco Data & Time | W1: Remark | X1: Party Code | Y1: Daybook Name | Z1: Company Clearing Document Number | AA1: Company Clearing Date | AB1: Company TDS Amount | AC1: Company Posting Date | AD1: Company Code | AE1: Supplier | AF1: Document Number | AG1: Business Area | AH1: Assignment | AI1: Document Header Text | AJ1: Tax Code | AK1: Year/Month | AL1: Reference | AM1: Profit Center | AN1: Posting Date | AO1: Amount in Doc. Curr. | AP1: Document Currency | AQ1: Local Currency | AR1: Entry Date | AS1: Withhldg Tax Base Amount | AT1: Payment Date
A2: e239eb4a-7f5d-409c-bd66-9768ff790717 | B2: dc9fa5fd-9a3f-406c-aee0-738399a743cd | C2: 0102bb94-b8cf-31a5-96a0-453f08501b67 | D2: Reconciled | E2: Date and Amount Matched | F2: ledger | G2: 06-06-2025 | H2: 7053011113 | I2: payment | J2: KZ | L2: 14451.72 | M2: ledger | N2: 06-06-2025 | P2: payment | Q2: DZ | R2: /103010300003186-AXIS Bank | S2: -14451.72 | T2: 0 | U2: PRI-PAY10.1-company | V2: 03-Aug-26 04:10 PM | X2: AAACI5569D | Z2: 7053011113 | AB2: 0 | AD2: EPL | AE2: 708659 | AF2: 7053011113 | AG2: EP00 | AH2: 20250606-SUM02 | AI2: 20250606-SUM02 | AK2: 2025/03 | AM2: 7200 | AN2: 06-06-2025 | AO2: 14451.72 | AP2: INR | AQ2: INR | AR2: 06-06-2025 | AS2: 12247.22 | AT2: 06-06-2025
A3: 34c18428-e172-4ed6-9cf3-9f84fa81647c | B3: 34d96bd4-ca8e-4393-87f5-55fa43df3b57 | C3: 01ccdb63-ed9f-36c5-9754-a6a656b0875b | D3: Reconciled | E3: Invoice Number Matched | F3: ledger | G3: 17-11-2025 | H3: GJ2501032777 | I3: invoice | J3: MA | K3: NITROGEN USP - NF / IH | L3: -15498.94 | M3: ledger | N3: 18-11-2025 | O3: GJ2501032777 | P3: invoice | Q3: RV | S3: 15498.94 | T3: 0 | U3: PRI-INV1.5_A-company | V3: 03-Aug-26 04:10 PM | X3: AAACI5569D | Z3: 7053043675 | AB3: 0 | AD3: EPL | AE3: 708659 | AF3: 6000012318 | AG3: EP00 | AH3: GJ2501032777 | AI3: GJ2501032777 | AJ3: II | AK3: 2025/08 | AL3: EP22 | AM3: 7200 | AN3: 27-11-2025 | AO3: -15498.94 | AP3: INR | AQ3: INR | AR3: 27-11-2025 | AS3: -13134.7 | AT3: 18-11-2025
A4: 770f1c2f-fb75-4346-bd2f-1689cc863585 | B4: 1fafef18-af9f-4680-8b53-63964cbe3e07 | C4: 03d9b23e-c626-3277-ba22-bf72070d5dee | D4: Write off / Rounding off | E4: Invoice Number Matched | F4: ledger | G4: 07-07-2025 | H4: GJ2501013614 | I4: invoice | J4: MA | K4: NITROGEN USP - NF / IH | L4: -16755 | M4: ledger | N4: 07-07-2025 | O4: GJ2501013614 | P4: invoice | Q4: RV | S4: 16755.62 | T4: 0.62 | U4: PRI-INV1.5-company | V4: 03-Aug-26 04:10 PM | X4: AAACI5569D | Z4: 7053018640 | AB4: 0 | AD4: EPL | AE4: 708659 | AF4: 6000004942 | AG4: EP00 | AH4: GJ2501013614 | AI4: GJ2501013614 | AJ4: IA | AK4: 2025/04 | AL4: EP22 | AM4: 7200 | AN4: 09-07-2025 | AO4: -16755 | AP4: INR | AQ4: INR | AR4: 09-07-2025 | AS4: -14199.06 | AT4: 07-07-2025
A5: b5f9bba9-6b13-4843-ad8a-f8819089a230 | B5: 42253461-935f-4b4e-bdc8-eade7b5f4ea7 | C5: 045af481-bc1a-3a4c-8216-2fe1a75b3cb2 | D5: Reconciled | E5: Invoice Number Matched | F5: ledger | G5: 13-08-2025 | H5: GJ2501019099 | I5: invoice | J5: MA | K5: NITROGEN USP - NF / IH | L5: -15498.94 | M5: ledger | N5: 13-08-2025 | O5: GJ2501019099 | P5: invoice | Q5: RV | S5: 15498.94 | T5: 0 | U5: PRI-INV1.5_A-company | V5: 03-Aug-26 04:10 PM | X5: AAACI5569D | Z5: 7053026128 | AB5: 0 | AD5: EPL | AE5: 708659 | AF5: 6000007799 | AG5: EP00 | AH5: GJ2501019099 | AI5: GJ2501019099 | AJ5: IA | AK5: 2025/05 | AL5: EP22 | AM5: 7200 | AN5: 28-08-2025 | AO5: -15498.94 | AP5: INR | AQ5: INR | AR5: 28-08-2025 | AS5: -13134.7 | AT5: 13-08-2025
A6: 75a1507e-8616-4f1c-8f6d-ed2c6ce945b7 | B6: 6d2b9e65-1ff0-4ec0-bcb6-6072ffcacd9e | C6: 05f512b8-4c97-3448-80b9-c21f5bc76dc4 | D6: Reconciled | E6: Date and Amount Matched | F6: ledger | G6: 25-06-2025 | H6: 7053014217 | I6: payment | J6: KZ | L6: 15498.94 | M6: ledger | N6: 25-06-2025 | P6: payment | Q6: DZ | R6: /103010300003186-AXIS Bank | S6: -15498.94 | T6: 0 | U6: PRI-PAY10.1-company | V6: 03-Aug-26 04:10 PM | X6: AAACI5569D | Z6: 7053014217 | AB6: 0 | AD6: EPL | AE6: 708659 | AF6: 7053014217 | AG6: EP00 | AH6: 20250625-SUM01 | AI6: 20250625-SUM01 | AK6: 2025/03 | AM6: 7200 | AN6: 25-06-2025 | AO6: 15498.94 | AP6: INR | AQ6: INR | AR6: 25-06-2025 | AS6: 13134.7 | AT6: 25-06-2025
A7: 2235a0a0-f99f-4b11-9ee9-56e6fbbd79e2 | B7: 0fd9a2cc-cf2f-47ef-be61-97e31aebc5e8 | C7: 0629eb8d-fb71-3eab-b7ee-962c818ce396 | D7: Reconciled | E7: Invoice Number Matched | F7: ledger | G7: 02-09-2025 | H7: GJ2501022123 | I7: invoice | J7: MA | K7: NITROGEN USP - NF / IH | L7: -19687.86 | M7: ledger | N7: 03-09-2025 | O7: GJ2501022123 | P7: invoice | Q7: RV | S7: 19687.86 | T7: 0 | U7: PRI-INV1.5_A-company | V7: 03-Aug-26 04:10 PM | X7: AAACI5569D | Z7: 7053028420 | AB7: 0 | AD7: EPL | AE7: 708659 | AF7: 6000008455 | AG7: EP00 | AH7: GJ2501022123 | AI7: GJ2501022123 | AJ7: IA | AK7: 2025/06 | AL7: EP22 | AM7: 7200 | AN7: 09-09-2025 | AO7: -19687.86 | AP7: INR | AQ7: INR | AR7: 09-09-2025 | AS7: -16684.62 | AT7: 03-09-2025
A8: b7155055-1caf-4e32-806b-aa52ab865971 | B8: ab22d0f7-095b-45c1-b856-a8d126e3953e | C8: 06915f1c-466a-37d8-a69e-5203e6977836 | D8: Reconciled | E8: Invoice Number Matched | F8: ledger | G8: 24-05-2025 | H8: GJ2501007303 | I8: invoice | J8: MA | K8: NITROGEN USP - NF / IH | L8: -14451.72 | M8: ledger | N8: 24-05-2025 | O8: GJ2501007303 | P8: invoice | Q8: RV | S8: 14451.72 | T8: 0 | U8: PRI-INV1.5_A-company | V8: 03-Aug-26 04:10 PM | X8: AAACI5569D | Z8: 7053011113 | AB8: 0 | AD8: EPL | AE8: 708659 | AF8: 6000002545 | AG8: EP00 | AH8: GJ2501007303 | AI8: GJ2501007303 | AJ8: IA | AK8: 2025/02 | AL8: EP22 | AM8: 7200 | AN8: 27-05-2025 | AO8: -14451.72 | AP8: INR | AQ8: INR | AR8: 27-05-2025 | AS8: -12247.22 | AT8: 26-05-2025
A9: 419f95e8-b40d-4a7d-875a-f77e13e3d13d | B9: f46a04d3-50f1-410f-9dc4-d32813671676 | C9: 0751589e-1f28-3d03-8a52-20da3026c011 | D9: Reconciled | E9: Date and Amount Matched | F9: ledger | G9: 03-12-2025 | H9: 7053044053 | I9: payment | J9: KZ | L9: 14451.72 | M9: ledger | N9: 03-12-2025 | P9: payment | Q9: DZ | R9: /103010300003186-AXIS Bank | S9: -14451.72 | T9: 0 | U9: PRI-PAY10.1-company | V9: 03-Aug-26 04:10 PM | X9: AAACI5569D | Z9: 7053044053 | AB9: 0 | AD9: EPL | AE9: 708659 | AF9: 7053044053 | AG9: EP00 | AH9: 20251203-SUM10 | AI9: 20251203-SUM10 | AK9: 2025/09 | AM9: 7200 | AN9: 03-12-2025 | AO9: 14451.72 | AP9: INR | AQ9: INR | AR9: 03-12-2025 | AS9: 12247.22 | AT9: 03-12-2025
A10: 7d1679e1-3bb1-4476-9a3e-ac8e0296508a | B10: ae90adba-0758-4a8b-a007-e0ac0a074a0f | C10: 08090543-befc-3333-abbb-055443e2311b | D10: Reconciled | E10: Date and Amount Matched | F10: ledger | G10: 12-11-2025 | H10: 7053039840 | I10: payment | J10: KZ | L10: 16755.62 | M10: ledger | N10: 12-11-2025 | P10: payment | Q10: DZ | R10: /103010300003186-AXIS Bank | S10: -16755.62 | T10: 0 | U10: PRI-PAY10.1-company | V10: 03-Aug-26 04:10 PM | X10: AAACI5569D | Z10: 7053039840 | AB10: 0 | AD10: EPL | AE10: 708659 | AF10: 7053039840 | AG10: EP00 | AH10: 20251112-SUM02 | AI10: 20251112-SUM02 | AK10: 2025/08 | AM10: 7200 | AN10: 12-11-2025 | AO10: 16755.62 | AP10: INR | AQ10: INR | AR10: 12-11-2025 | AS10: 14199.68 | AT10: 12-11-2025
A11: 4fa6e103-8352-4fa5-82c2-8ad1a9ac9546 | B11: 22851b8b-1969-4590-a3b5-8d6620d3dee0 | C11: 0a46fe88-ffcf-3e58-ad12-81417f99e660 | D11: Reconciled | E11: Date and Amount Matched | F11: ledger | G11: 10-12-2025 | H11: 7053045044 | I11: payment | J11: KZ | L11: 13613.94 | M11: ledger | N11: 10-12-2025 | P11: payment | Q11: DZ | R11: /103010300003186-AXIS Bank | S11: -13613.94 | T11: 0 | U11: PRI-PAY10.1-company | V11: 03-Aug-26 04:10 PM | X11: AAACI5569D | Z11: 7053045044 | AB11: 0 | AD11: EPL | AE11: 708659 | AF11: 7053045044 | AG11: EP00 | AH11: 20251210-SUM02 | AI11: 20251210-SUM02 | AK11: 2025/09 | AM11: 7200 | AN11: 10-12-2025 | AO11: 13613.94 | AP11: INR | AQ11: INR | AR11: 10-12-2025 | AS11: 11537.24 | AT11: 10-12-2025
A12: 1a922d31-d186-4e4c-aa1f-f2289a8a79d4 | B12: 8b8a393a-e179-46b1-8dd9-cbc5938ded87 | C12: 0ad380c7-d851-32e8-a15f-148dccd6158d | D12: Reconciled | E12: Invoice Number Matched | F12: ledger | G12: 27-11-2025 | H12: GJ2501034356 | I12: invoice | J12: MA | K12: NITROGEN USP - NF / IH | L12: -15498.94 | M12: ledger | N12: 28-11-2025 | O12: GJ2501034356 | P12: invoice | Q12: RV | S12: 15498.94 | T12: 0 | U12: PRI-INV1.5_A-company | V12: 03-Aug-26 04:10 PM | X12: AAACI5569D | Z12: 7053045773 | AB12: 0 | AD12: EPL | AE12: 708659 | AF12: 6000012593 | AG12: EP00 | AH12: GJ2501034356 | AI12: GJ2501034356 | AJ12: II | AK12: 2025/09 | AL12: EP22 | AM12: 7200 | AN12: 01-12-2025 | AO12: -15498.94 | AP12: INR | AQ12: INR | AR12: 01-12-2025 | AS12: -13134.7 | AT12: 28-11-2025
A13: b774ef5e-3b11-4525-b185-71d8da4ef911 | B13: e9d901d3-899f-4f0f-9526-7a583554dc58 | C13: 0c3f5a3b-3748-3cfb-9475-17d40608f144 | D13: Reconciled | E13: Date and Amount Matched | F13: ledger | G13: 20-03-2026 | H13: 7053065837 | I13: payment | J13: KZ | L13: 38859 | M13: ledger | N13: 20-03-2026 | P13: payment | Q13: DZ | R13: NEFT Cr-UTIB0001636-EMCURE PHARMACEUTICALS LIMITED | S13: -38859 | T13: 0 | U13: PRI-PAY10.1-company | V13: 03-Aug-26 04:10 PM | X13: AAACI5569D | Z13: 7053065837 | AB13: 0 | AD13: EPL | AE13: 714213 | AF13: 7053065837 | AG13: EP00 | AH13: 20260320-SUM01 | AI13: 20260320-SUM01 | AK13: 2025/12 | AM13: 7200 | AN13: 20-03-2026 | AO13: 38859 | AP13: INR | AQ13: INR | AR13: 20-03-2026 | AS13: 32931.360000000001 | AT13: 20-03-2026
A14: 978a5118-8f9b-4f54-ab7b-de26a6e84029 | B14: 1753e470-c31e-44ee-8c22-932192d984dc | C14: 0ca1f6e1-3818-37d8-abe4-e28760ace981 | D14: TDS Booked by Company | E14: Invoice Number Matched | F14: ledger | G14: 05-07-2025 | H14: GJ2502001220 | I14: invoice | J14: MI | K14: Fixed facility charges july-25 | L14: -8120 | M14: ledger | N14: 05-07-2025 | O14: GJ2502001220 | P14: invoice | Q14: RV | S14: 8260 | T14: 140 | U14: PRI-INV1.6-company | V14: 03-Aug-26 04:10 PM | X14: AAACI5569D | Z14: 7053018640 | AB14: -140 | AD14: EPL | AE14: 708659 | AF14: 6008011428 | AG14: EP00 | AH14: GJ2502001220 | AI14: GJ2502001220 | AJ14: IA | AK14: 2025/04 | AL14: EP22 | AM14: 7200 | AN14: 14-07-2025 | AO14: -8120 | AP14: INR | AQ14: INR | AR14: 14-07-2025 | AS14: -7000 | AT14: 09-07-2025
A15: 72be1a7e-de00-4fd0-8e54-9f420150202c | B15: 68db1cf9-695a-4338-8441-6d672543df07 | C15: 0d6f58c1-3d6a-3d8d-a262-9322227f107c | D15: Write off / Rounding off | E15: Invoice Number Matched | F15: ledger | G15: 03-01-2026 | H15: GJ2501039969 | I15: invoice | J15: MA | K15: NITROGEN USP - NF /Ph.Eur./IH | L15: -64849 | M15: ledger | N15: 03-01-2026 | O15: GJ2501039969 | P15: invoice | Q15: RV | S15: 64849.12 | T15: 0.12 | U15: PRI-INV1.5-company | V15: 03-Aug-26 04:10 PM | X15: AAACI5569D | Z15: 7053062135 | AB15: 0 | AD15: EPL | AE15: 714213 | AF15: 6000015127 | AG15: EP00 | AH15: GJ2501039969 | AI15: GJ501039969 | AJ15: II | AK15: 2025/10 | AL15: EP22 | AM15: 7200 | AN15: 08-01-2026 | AO15: -64849 | AP15: INR | AQ15: INR | AR15: 08-01-2026 | AS15: -54956.76 | AT15: 05-02-2026
A16: 18a22fcd-aa46-43ba-bea8-a7df2be52ecf | B16: fb427b4a-0596-41c3-b838-4d2490b3b7fd | C16: 0ddc8c6f-8b90-34e4-8974-3667e8ffe791 | D16: TDS Booked by Company | E16: Invoice Number Matched | F16: ledger | G16: 05-06-2025 | H16: GJ2502000831 | I16: invoice | J16: MI | K16: Rent charges of nitrogen for June 25 | L16: -8120 | M16: ledger | N16: 05-06-2025 | O16: GJ2502000831 | P16: invoice | Q16: RV | S16: 8260 | T16: 140 | U16: PRI-INV1.6-company | V16: 03-Aug-26 04:10 PM | X16: AAACI5569D | Z16: 7053046690 | AB16: -140 | AD16: EPL | AE16: 708659 | AF16: 6008028039 | AG16: EP00 | AH16: GJ2502000831 | AI16: GJ2502000831 | AJ16: II | AK16: 2025/09 | AL16: EP22 | AM16: 7200 | AN16: 03-12-2025 | AO16: -8120 | AP16: INR | AQ16: INR | AR16: 03-12-2025 | AS16: -7000 | AT16: 21-11-2025
A17: 170e69cc-07fd-4cb5-9794-83d05841139c | B17: 59c3147f-8d47-4538-b89e-eb33f76b06cb | C17: 0dfbfa1c-a556-3548-86cf-642408720a57 | D17: Reconciled | E17: Invoice Number Matched | F17: ledger | G17: 28-07-2025 | H17: GJ2501016823 | I17: invoice | J17: MA | K17: NITROGEN USP - NF / IH | L17: -11938.37 | M17: ledger | N17: 28-07-2025 | O17: GJ2501016823 | P17: invoice | Q17: RV | S17: 11938.37 | T17: 0 | U17: PRI-INV1.5_A-company | V17: 03-Aug-26 04:10 PM | X17: AAACI5569D | Z17: 7053022562 | AB17: 0 | AD17: EPL | AE17: 708659 | AF17: 6000006496 | AG17: EP00 | AH17: GJ2501016823 | AI17: GJ2501016823 | AJ17: IA | AK17: 2025/04 | AL17: EP22 | AM17: 7200 | AN17: 31-07-2025 | AO17: -11938.37 | AP17: INR | AQ17: INR | AR17: 31-07-2025 | AS17: -10117.27 | AT17: 28-07-2025
A18: 619e07ca-fb10-4050-8184-91b2cd0ea0cb | B18: 381048b6-4c9b-46f2-9394-3addac6a373c | C18: 0f0198d3-9f6b-3a13-94bd-40f5464d2661 | D18: Reconciled | E18: Invoice Number Matched | F18: ledger | G18: 27-05-2025 | H18: GJ2501007694 | I18: invoice | J18: MA | K18: NITROGEN USP - NF / IH | L18: -17802.84 | M18: ledger | N18: 27-05-2025 | O18: GJ2501007694 | P18: invoice | Q18: RV | S18: 17802.84 | T18: 0 | U18: PRI-INV1.5_A-company | V18: 03-Aug-26 04:10 PM | X18: AAACI5569D | Z18: 7053011696 | AB18: 0 | AD18: EPL | AE18: 708659 | AF18: 6000002794 | AG18: EP00 | AH18: GJ2501007694 | AI18: GJ2501007694 | AJ18: IA | AK18: 2025/03 | AL18: EP22 | AM18: 7200 | AN18: 02-06-2025 | AO18: -17802.84 | AP18: INR | AQ18: INR | AR18: 02-06-2025 | AS18: -15087.16 | AT18: 28-05-2025
A19: 537db7e4-5131-4d30-ad04-e8a3bda13f80 | B19: 16d98f5b-7192-4f4f-9581-3d76cc11477d | C19: 0f6b9183-9481-3ca8-ad34-d9c464fc060c | D19: Reconciled | E19: Invoice Number Matched | F19: ledger | G19: 27-01-2026 | H19: GJ2501043584 | I19: invoice | J19: MA | K19: NITROGEN USP - NF / IH | L19: -14661.16 | M19: ledger | N19: 27-01-2026 | O19: GJ2501043584 | P19: invoice | Q19: RV | S19: 14661.16 | T19: 0 | U19: PRI-INV1.5_A-company | V19: 03-Aug-26 04:10 PM | X19: AAACI5569D | Z19: 7053058317 | AB19: 0 | AD19: EPL | AE19: 708659 | AF19: 6000016109 | AG19: EP00 | AH19: GJ2501043584 | AI19: GJ2501043584 | AJ19: II | AK19: 2025/10 | AL19: EP22 | AM19: 7200 | AN19: 29-01-2026 | AO19: -14661.16 | AP19: INR | AQ19: INR | AR19: 29-01-2026 | AS19: -12424.72 | AT19: 28-01-2026
A20: 7e32b000-4c36-41d5-ad50-2d95744cc8e8 | B20: d9b5b396-0cb9-4308-a2b6-5845677070b8 | C20: 1042934f-e325-3aa2-b1e6-67ce509b480f | D20: Reconciled | E20: Date and Amount Matched | F20: ledger | G20: 21-04-2025 | H20: 7053003056 | I20: payment | J20: KZ | L20: 18431.19 | M20: ledger | N20: 21-04-2025 | P20: payment | Q20: DZ | R20: /103010300003186-AXIS Bank | S20: -18431.19 | T20: 0 | U20: PRI-PAY10.1-company | V20: 03-Aug-26 04:10 PM | X20: AAACI5569D | Z20: 7053003056 | AB20: 0 | AD20: EPL | AE20: 708659 | AF20: 7053003056 | AG20: EP00 | AH20: 20250421-SUM02 | AI20: 20250421-SUM02 | AK20: 2025/01 | AM20: 7200 | AN20: 21-04-2025 | AO20: 18431.189999999999 | AP20: INR | AQ20: INR | AR20: 21-04-2025 | AS20: 15619.65 | AT20: 21-04-2025
A21: 2568f5d0-48d2-44bd-acf6-9f2158611cba | B21: 77d26c2e-a512-4b25-b25d-43a78503a417 | C21: 106c61c6-f08b-3269-8369-81e371ed4e6d | D21: Reconciled | E21: Invoice Number Matched | F21: ledger | G21: 16-09-2025 | H21: GJ2501017485 | I21: invoice | J21: MA | K21: NITROGEN USP - NF / IH | L21: -17174.51 | M21: ledger | N21: 01-08-2025 | O21: GJ2501017485 | P21: invoice | Q21: RV | S21: 17174.51 | T21: 0 | U21: PRI-INV1.5_A-company | V21: 03-Aug-26 04:10 PM | X21: AAACI5569D | Z21: 7053034627 | AB21: 0 | AD21: EPL | AE21: 708659 | AF21: 6000009736 | AG21: EP00 | AH21: GJ2501017485 | AI21: GJ2501024363 | AJ21: II | AK21: 2025/06 | AL21: EP22 | AM21: 7200 | AN21: 30-09-2025 | AO21: -17174.509999999998 | AP21: INR | AQ21: INR | AR21: 30-09-2025 | AS21: -14554.67 | AT21: 01-08-2025
A22: 824c4c97-c29f-47f9-874f-8ff4134020b3 | B22: c6538111-bb2a-42b4-a133-51eb04f5c1c2 | C22: 110c9077-55d7-366f-901a-689dd1a2b184 | D22: Reconciled | E22: Date and Amount Matched | F22: ledger | G22: 28-05-2025 | H22: 7053009537 | I22: payment | J22: KZ | L22: 31207 | M22: ledger | N22: 28-05-2025 | P22: payment | Q22: DZ | R22: /103010300003186-AXIS Bank | S22: -31207 | T22: 0 | U22: PRI-PAY10.1-company | V22: 03-Aug-26 04:10 PM | X22: AAACI5569D | Z22: 7053009537 | AB22: 0 | AD22: EPL | AE22: 708659 | AF22: 7053009537 | AG22: EP00 | AH22: 20250528-SUM01 | AI22: 20250528-SUM01 | AK22: 2025/02 | AM22: 7200 | AN22: 28-05-2025 | AO22: 31207 | AP22: INR | AQ22: INR | AR22: 28-05-2025 | AS22: 26446.560000000001 | AT22: 28-05-2025
A23: a9dc7e96-48ff-47e7-95e7-1378163d69a3 | B23: bf5d9d3a-9642-4dec-a100-e2a69c626181 | C23: 12865390-331f-3113-9500-42d98c7e89c1 | D23: TDS Booked by Company | E23: Invoice Number Matched | F23: ledger | G23: 16-01-2026 | H23: GJ2502003787 | I23: invoice | J23: MI | K23: CONSULTANCY FEES- APPROX MONTH JAN 2025 | L23: -121800 | M23: ledger | N23: 16-01-2026 | O23: GJ2502003787 | P23: invoice | Q23: RV | S23: 123900 | T23: 2100 | U23: PRI-INV1.6-company | V23: 03-Aug-26 04:10 PM | X23: AAACI5569D | Z23: 7053056142 | AB23: -2100 | AD23: EPL | AE23: 708659 | AF23: 6008034932 | AG23: EP00 | AH23: GJ2502003787 | AI23: GJ2502003787 | AJ23: II | AK23: 2025/10 | AL23: EP22 | AM23: 7200 | AN23: 21-01-2026 | AO23: -121800 | AP23: INR | AQ23: INR | AR23: 21-01-2026 | AS23: -105000 | AT23: 20-01-2026
A24: 241dd284-d5a2-41cc-910d-d161ab84c990 | B24: decaaf4c-de4c-42bb-9f1a-fa2c1619ea9c | C24: 12c5ebd7-0bc5-3cb6-988a-a352ffa8c7dd | D24: Reconciled | E24: Date and Amount Matched | F24: ledger | G24: 29-01-2026 | H24: 7053055473 | I24: payment | J24: KZ | L24: 16127.29 | M24: ledger | N24: 29-01-2026 | P24: payment | Q24: DZ | R24: /103010300003186-AXIS Bank | S24: -16127.29 | T24: 0 | U24: PRI-PAY10.1-company | V24: 03-Aug-26 04:10 PM | X24: AAACI5569D | Z24: 7053055473 | AB24: 0 | AD24: EPL | AE24: 708659 | AF24: 7053055473 | AG24: EP00 | AH24: 20260129-SUM10 | AI24: 20260129-SUM10 | AK24: 2025/10 | AM24: 7200 | AN24: 29-01-2026 | AO24: 16127.29 | AP24: INR | AQ24: INR | AR24: 29-01-2026 | AS24: 13667.19 | AT24: 29-01-2026
A25: 5fbc469c-a265-4725-a34e-e3e6e122d815 | B25: 1b7bc51b-ebf7-45d6-8b00-73a7c0d47ffe | C25: 12df1500-5005-40c3-85f2-7d0f4e5e944e | D25: Reconciled | E25: Date Range and Amount Matched | F25: ledger | G25: 10-11-2025 | H25: 7053039489 | I25: payment | J25: KZ | L25: 55663.4 | M25: ledger | N25: 11-11-2025 | P25: payment | Q25: DZ | R25: /103010300003186-AXIS Bank | S25: -55663.4 | T25: 0 | U25: PRI-PAY11.1-company | V25: 03-Aug-26 04:10 PM | X25: AAACI5569D | Z25: 7053039489 | AB25: 0 | AD25: EPL | AE25: 708659 | AF25: 7053039489 | AG25: EP00 | AH25: 20251110-SUM02 | AI25: 20251110-SUM02 | AK25: 2025/08 | AM25: 7200 | AN25: 10-11-2025 | AO25: 55663.4 | AP25: INR | AQ25: INR | AR25: 10-11-2025 | AS25: 47290.92 | AT25: 10-11-2025
A26: 313fcd04-0514-4321-b7ea-bd5e17850e66 | B26: f879ae48-5e10-422c-abc1-fd7fb567032a | C26: 134030d4-0656-306c-923c-0033ee196bb6 | D26: Reconciled | E26: Date and Amount Matched | F26: ledger | G26: 23-03-2026 | H26: 7053065992 | I26: payment | J26: KZ | L26: 36588.02 | M26: ledger | N26: 23-03-2026 | P26: payment | Q26: DZ | R26: NEFT Cr-UTIB0001636-EMCURE PHARMACEUTICALS LIMITED | S26: -36588.02 | T26: 0 | U26: PRI-PAY10.1-company | V26: 03-Aug-26 04:10 PM | X26: AAACI5569D | Z26: 7053065992 | AB26: 0 | AD26: EPL | AE26: 714213 | AF26: 7053065992 | AG26: EP00 | AH26: 20260323-SUM10 | AI26: 20260323-SUM10 | AK26: 2025/12 | AM26: 7200 | AN26: 23-03-2026 | AO26: 36588.019999999997 | AP26: INR | AQ26: INR | AR26: 23-03-2026 | AS26: 31006.799999999999 | AT26: 23-03-2026
A27: 9c49830e-2d1e-42b9-815f-086292e35a0a | B27: 04d81620-531e-4e19-88ee-107613bd869b | C27: 1389c6c3-a6c5-3e19-86d9-0c8da1f05247 | D27: Reconciled | E27: Invoice Number Matched | F27: ledger | G27: 27-08-2025 | H27: GJ2501021121 | I27: invoice | J27: MA | K27: NITROGEN USP - NF / IH | L27: -18431.19 | M27: ledger | N27: 27-08-2025 | O27: GJ2501021121 | P27: invoice | Q27: RV | S27: 18431.19 | T27: 0 | U27: PRI-INV1.5_A-company | V27: 03-Aug-26 04:10 PM | X27: AAACI5569D | Z27: 7053028415 | AB27: 0 | AD27: EPL | AE27: 708659 | AF27: 6000008256 | AG27: EP00 | AH27: GJ2501021121 | AI27: GJ2501021121 | AJ27: IA | AK27: 2025/06 | AL27: EP22 | AM27: 7200 | AN27: 04-09-2025 | AO27: -18431.189999999999 | AP27: INR | AQ27: INR | AR27: 04-09-2025 | AS27: -15619.65 | AT27: 30-08-2025
A28: 20d86c9d-20cf-452b-b863-4d4161757ce2 | B28: 223b4917-7bb6-4d0b-a1e6-1a09de4e5ba4 | C28: 14106f01-4bbc-3296-9e9f-428271999dbc | D28: Write off / Rounding off | E28: Invoice Number Matched | F28: ledger | G28: 13-09-2025 | H28: GJ2501023625 | I28: invoice | J28: MA | K28: NITROGEN USP - NF / IH | L28: -17803 | M28: ledger | N28: 13-09-2025 | O28: GJ2501023625 | P28: invoice | Q28: RV | S28: 17802.84 | T28: -0.16 | U28: PRI-INV1.5-company | V28: 03-Aug-26 04:10 PM | X28: AAACI5569D | Z28: 7053031026 | AB28: 0 | AD28: EPL | AE28: 708659 | AF28: 6000009286 | AG28: EP00 | AH28: GJ2501023625 | AI28: GJ2501023625 | AJ28: II | AK28: 2025/06 | AL28: EP22 | AM28: 7200 | AN28: 24-09-2025 | AO28: -17803 | AP28: INR | AQ28: INR | AR28: 24-09-2025 | AS28: -15087.32 | AT28: 15-09-2025
A29: ef3174fa-b20c-4650-a437-2c28e373cc6b | B29: c217d3b2-dc98-4972-a22c-62690237c23d | C29: 1458031b-5016-3393-abba-62c141df9776 | D29: Reconciled | E29: Invoice Number Matched | F29: ledger | G29: 21-12-2025 | H29: GJ2501038191 | I29: invoice | J29: MA | K29: NITROGEN USP - NF / IH | L29: -16127.29 | M29: ledger | N29: 23-12-2025 | O29: GJ2501038191 | P29: invoice | Q29: RV | S29: 16127.29 | T29: 0 | U29: PRI-INV1.5_A-company | V29: 03-Aug-26 04:10 PM | X29: AAACI5569D | Z29: 7053052837 | AB29: 0 | AD29: EPL | AE29: 708659 | AF29: 6000014800 | AG29: EP00 | AH29: GJ2501038191 | AI29: GJ2501038191 | AJ29: II | AK29: 2025/09 | AL29: EP22 | AM29: 7200 | AN29: 31-12-2025 | AO29: -16127.29 | AP29: INR | AQ29: INR | AR29: 02-01-2026 | AS29: -13667.19 | AT29: 23-12-2025
A30: 13a89072-17f4-469b-adab-904e77bee999 | B30: 80f73e0c-33e6-46c1-8d62-587bbc3a6ddb | C30: 161da05b-906d-3575-9250-bfbc809ee54f | D30: TDS Booked by Company | E30: Invoice Number Matched | F30: ledger | G30: 05-02-2026 | H30: GJ2502003996 | I30: invoice | J30: MI | K30: Nitrogen tank 6kl Rent Charge (Inox) | L30: -29000 | M30: ledger | N30: 05-02-2026 | O30: GJ2502003996 | P30: invoice | Q30: RV | S30: 29500 | T30: 500 | U30: PRI-INV1.6-company | V30: 03-Aug-26 04:10 PM | X30: AAACI5569D | Z30: 7053062135 | AB30: -500 | AD30: EPL | AE30: 714213 | AF30: 6008037710 | AG30: EP00 | AH30: GJ2502003996 | AI30: GJ2502003996 | AJ30: II | AK30: 2025/11 | AL30: EP22 | AM30: 7200 | AN30: 12-02-2026 | AO30: -29000 | AP30: INR | AQ30: INR | AR30: 12-02-2026 | AS30: -25000 | AT30: 10-02-2026
A31: 950366d2-bbd9-4aa1-91a6-3874647c2db4 | B31: f3de4390-0fc5-4dde-bb2f-51aac3816e1a | C31: 165c1b3d-a552-3e10-b987-25b57387d0ee | D31: Reconciled | E31: Invoice Number Matched | F31: ledger | G31: 04-04-2025 | H31: GJ2501000356 | I31: invoice | J31: MA | K31: NITROGEN USP - NF / IH | L31: -17802.84 | M31: ledger | N31: 04-04-2025 | O31: GJ2501000356 | P31: invoice | Q31: RV | S31: 17802.84 | T31: 0 | U31: PRI-INV1.5_A-company | V31: 03-Aug-26 04:10 PM | X31: AAACI5569D | Z31: 7053003202 | AB31: 0 | AD31: EPL | AE31: 708659 | AF31: 6000000634 | AG31: EP00 | AH31: GJ2501000356 | AI31: GJ2501000356 | AJ31: IA | AK31: 2025/01 | AL31: EP22 | AM31: 7200 | AN31: 21-04-2025 | AO31: -17802.84 | AP31: INR | AQ31: INR | AR31: 21-04-2025 | AS31: -15087.16 | AT31: 03-04-2025
A32: 3459e23a-ac4a-4af6-8300-ec0ed529935d | B32: 0320d7df-9a8d-4d25-9dc8-f3bc70fe582e | C32: 17c0c9f1-a4e5-32fd-b0c2-d53b07c35f44 | D32: Reconciled | E32: Invoice Number Matched | F32: ledger | G32: 01-02-2026 | H32: GJ2501044504 | I32: invoice | J32: MA | K32: NITROGEN USP - NF / IH | L32: -15289.51 | M32: ledger | N32: 01-02-2026 | O32: GJ2501044504 | P32: invoice | Q32: RV | S32: 15289.51 | T32: 0 | U32: PRI-INV1.5_A-company | V32: 03-Aug-26 04:10 PM | X32: AAACI5569D | Z32: 7053058939 | AB32: 0 | AD32: EPL | AE32: 708659 | AF32: 6000016636 | AG32: EP00 | AH32: GJ2501044504 | AI32: GJ2501044504 | AJ32: II | AK32: 2025/11 | AL32: EP22 | AM32: 7200 | AN32: 06-02-2026 | AO32: -15289.51 | AP32: INR | AQ32: INR | AR32: 06-02-2026 | AS32: -12957.21 | AT32: 02-02-2026
A33: dccf8b26-0e80-4223-8058-0c6172df8eba | B33: 969ca46e-22f0-4074-a516-d83e25f51713 | C33: 18c90947-08ce-3d07-8cdf-d8ddf23b1be2 | D33: Reconciled | E33: Date and Amount Matched | F33: ledger | G33: 04-06-2025 | H33: 7053010772 | I33: payment | J33: KZ | L33: 31206 | M33: ledger | N33: 04-06-2025 | P33: payment | Q33: DZ | R33: /103010300003186-AXIS Bank | S33: -31206 | T33: 0 | U33: PRI-PAY10.1-company | V33: 03-Aug-26 04:10 PM | X33: AAACI5569D | Z33: 7053010772 | AB33: 0 | AD33: EPL | AE33: 708659 | AF33: 7053010772 | AG33: EP00 | AH33: 20250604-SUM02 | AI33: 20250604-SUM02 | AK33: 2025/03 | AM33: 7200 | AN33: 04-06-2025 | AO33: 31206 | AP33: INR | AQ33: INR | AR33: 04-06-2025 | AS33: 26445.56 | AT33: 04-06-2025
A34: d443d5bb-02a1-47d3-81cc-d8c9187ab4ef | B34: 912c5f17-4bc3-4292-bedd-c4853c791d10 | C34: 194b8823-59b1-3caa-8a44-6e333f1a9231 | D34: Reconciled | E34: Invoice Number Matched | F34: ledger | G34: 13-12-2025 | H34: GJ2501036831 | I34: invoice | J34: MA | K34: NITROGEN USP - NF / IH | L34: -14870.62 | M34: ledger | N34: 14-12-2025 | O34: GJ2501036831 | P34: invoice | Q34: RV | S34: 14870.62 | T34: 0 | U34: PRI-INV1.5_A-company | V34: 03-Aug-26 04:10 PM | X34: AAACI5569D | Z34: 7053048840 | AB34: 0 | AD34: EPL | AE34: 708659 | AF34: 6000013561 | AG34: EP00 | AH34: GJ2501036831 | AI34: GJ2501036831 | AJ34: II | AK34: 2025/09 | AL34: EP22 | AM34: 7200 | AN34: 18-12-2025 | AO34: -14870.62 | AP34: INR | AQ34: INR | AR34: 18-12-2025 | AS34: -12602.22 | AT34: 13-12-2025
A35: dc257bdb-875c-466b-88f2-40a6f8bfcc5e | B35: 58f60edc-1f82-411d-9f23-a773bc3f54a6 | C35: 1a75c43e-9692-3b49-a0ca-b819f205b2ba | D35: Reconciled | E35: Date and Amount Matched | F35: ledger | G35: 24-12-2025 | H35: 7053047776 | I35: payment | J35: KZ | L35: 29531 | M35: ledger | N35: 24-12-2025 | P35: payment | Q35: DZ | R35: /103010300003186-AXIS Bank | S35: -29531 | T35: 0 | U35: PRI-PAY10.1-company | V35: 03-Aug-26 04:10 PM | X35: AAACI5569D | Z35: 7053047776 | AB35: 0 | AD35: EPL | AE35: 708659 | AF35: 7053047776 | AG35: EP00 | AH35: 20251224-SUM01 | AI35: 20251224-SUM01 | AK35: 2025/09 | AM35: 7200 | AN35: 24-12-2025 | AO35: 29531 | AP35: INR | AQ35: INR | AR35: 24-12-2025 | AS35: 25026.16 | AT35: 24-12-2025
A36: c86cceed-0cec-4bce-881b-9e889fa9534a | B36: 3caa2a32-692a-45a7-b31f-4bc48d5ecee1 | C36: 1b464bbe-c278-3e49-948f-b1263bd94f23 | D36: Reconciled | E36: Invoice Number Matched | F36: ledger | G36: 29-11-2025 | H36: GJ2501034724 | I36: invoice | J36: MA | K36: NITROGEN USP - NF / IH | L36: -12985.61 | M36: ledger | N36: 30-11-2025 | O36: GJ2501034724 | P36: invoice | Q36: RV | S36: 12985.61 | T36: 0 | U36: PRI-INV1.5_A-company | V36: 03-Aug-26 04:10 PM | X36: AAACI5569D | Z36: 7053047188 | AB36: 0 | AD36: EPL | AE36: 708659 | AF36: 6000013502 | AG36: EP00 | AH36: GJ2501034724 | AI36: GJ2501034724 | AJ36: II | AK36: 2025/09 | AL36: EP22 | AM36: 7200 | AN36: 18-12-2025 | AO36: -12985.61 | AP36: INR | AQ36: INR | AR36: 18-12-2025 | AS36: -11004.75 | AT36: 02-12-2025
A37: ed421c7a-fe50-45b8-9bd6-5d949c6cd7ea | B37: 990c846b-d514-4741-98f9-d63b6127bc7f | C37: 1c189260-3413-3264-8ec4-304bb0a4a29c | D37: Write off / Rounding off | E37: Invoice Number Matched | F37: ledger | G37: 30-03-2026 | H37: GJ2501053696 | I37: invoice | J37: MA | K37: NITROGEN USP - NF /Ph.Eur./IH | L37: -24728 | M37: ledger | N37: 30-03-2026 | O37: GJ2501053696 | P37: invoice | Q37: RV | S37: 24728.46 | T37: 0.46 | U37: PRI-INV1.5-company | V37: 03-Aug-26 04:10 PM | X37: AAACI5569D | Z37: 7053002120 | AB37: 0 | AD37: EPL | AE37: 714213 | AF37: 6000019806 | AG37: EP00 | AH37: GJ2501053696 | AI37: GJ2501053696 | AJ37: II | AK37: 2025/12 | AL37: EP22 | AM37: 7200 | AN37: 31-03-2026 | AO37: -24728 | AP37: INR | AQ37: INR | AR37: 31-03-2026 | AS37: -20955.86 | AT37: 31-03-2026
A38: 48ec9e30-b538-4174-ac1c-cb0ef9dff214 | B38: 34cd6a9b-9985-4b4a-92c8-97e6dcb31a11 | C38: 1c1b6223-e656-3a45-8026-dfe15012b0b4 | D38: Reconciled | E38: Multiple Date and Amount Matched | F38: ledger | G38: 05-05-2025 | H38: 7053005096 | I38: payment | J38: KZ | L38: 15498.94 | M38: ledger | N38: 05-05-2025 | P38: payment | Q38: DZ | R38: /103010300003186-AXIS Bank | S38: -15498.94 | T38: 0 | U38: PRI-PAY1.1-company | V38: 03-Aug-26 04:10 PM | X38: AAACI5569D | Z38: 7053005096 | AB38: 0 | AD38: EPL | AE38: 708659 | AF38: 7053005096 | AG38: EP16 | AH38: 20250505-SUM10 | AI38: 20250505-SUM10 | AK38: 2025/02 | AM38: 7200 | AN38: 05-05-2025 | AO38: 15498.94 | AP38: INR | AQ38: INR | AR38: 05-05-2025 | AS38: 13134.7 | AT38: 05-05-2025
A39: 7364a35b-7b93-41b1-9d9b-0410d48cb70a | B39: c03d826c-ca9d-4ceb-ada9-b6eea7ea14c1 | C39: 1c1b6223-e656-3a45-8026-dfe15012b0b4 | D39: Reconciled | E39: Multiple Date and Amount Matched | F39: ledger | G39: 05-05-2025 | H39: 7053005095 | I39: payment | J39: KZ | L39: 95505.13 | M39: ledger | N39: 05-05-2025 | P39: payment | Q39: DZ | R39: /103010300003186-AXIS Bank | S39: -95505.13 | T39: 0 | U39: PRI-PAY1.1-company | V39: 03-Aug-26 04:10 PM | X39: AAACI5569D | Z39: 7053005095 | AB39: 0 | AD39: EPL | AE39: 708659 | AF39: 7053005095 | AG39: EP00 | AH39: 20250505-SUM10 | AI39: 20250505-SUM10 | AK39: 2025/02 | AM39: 7200 | AN39: 05-05-2025 | AO39: 95505.13 | AP39: INR | AQ39: INR | AR39: 05-05-2025 | AS39: 80936.25 | AT39: 05-05-2025
A40: 6e05986c-f44b-4328-a278-7f5c7eb32394 | B40: 341e14db-7a60-4284-9554-eda308453feb | C40: 1c79962d-b9e7-3e4d-b6b6-f28d16f13cd6 | D40: Write off / Rounding off | E40: Invoice Number Matched | F40: ledger | G40: 18-11-2025 | H40: GJ2501032941 | I40: invoice | J40: MA | K40: NITROGEN USP - NF / IH | L40: -15080 | M40: ledger | N40: 19-11-2025 | O40: GJ2501032941 | P40: invoice | Q40: RV | S40: 15080.05 | T40: 0.05 | U40: PRI-INV1.5-company | V40: 03-Aug-26 04:10 PM | X40: AAACI5569D | Z40: 7053043908 | AB40: 0 | AD40: EPL | AE40: 708659 | AF40: 6000012320 | AG40: EP00 | AH40: GJ2501032941 | AI40: GJ2501032941 | AJ40: II | AK40: 2025/08 | AL40: EP22 | AM40: 7200 | AN40: 27-11-2025 | AO40: -15080 | AP40: INR | AQ40: INR | AR40: 27-11-2025 | AS40: -12779.66 | AT40: 20-11-2025
...

Sheet 1
A1: Party Id | B1: Matched Id | C1: Status | D1: Classification | E1: Company Statement Type | F1: Company Invoice Date | G1: Company Invoice Number | H1: Company DocType | I1: Company Original DocType | J1: Company Amount | K1: Party Statement Type | L1: Party Invoice Date | M1: Party Invoice Number | N1: Party DocType | O1: Party Original DocType | P1: Party Amount | Q1: Difference | R1: Party Clearing Document Number | S1: Party Clearing Date | T1: Party TDS Amount | U1: Party Posting Date | V1: Profit Center | W1: Document Number | X1: Billing Document | Y1: Document Header Text
A2: 83367621-45ac-4bfa-a27d-253caf496027 | C2: Invoice not booked by Company | D2: Unmatched | J2: 0 | K2: ledger | L2: 26-02-2026 | M2: GJ2501048647 | N2: invoice | O2: RV | P2: 34947.88 | Q2: 34947.88 | R2: 200019483 | S2: 18-05-2026 | T2: 0 | U2: 26-02-2026 | V2: 2121 | W2: 391913 | X2: 96042661
A3: 4e6a339d-98e1-45b0-a6c6-8c09b206b35d | C3: Invoice not booked by Company | D3: Unmatched | J3: 0 | K3: ledger | L3: 05-03-2026 | M3: GJ2502004390 | N3: invoice | O3: RV | P3: 29500 | Q3: 29500 | R3: 200014107 | S3: 30-04-2026 | T3: 0 | U3: 05-03-2026 | V3: 2121 | W3: 400046 | X3: 96050793
A4: 9420b795-bb86-4f11-9192-58449f7a6019 | C4: Invoice not booked by Company | D4: Unmatched | J4: 0 | K4: ledger | L4: 01-04-2025 | N4: invoice | O4: RV | P4: 139909.44 | Q4: 139909.44 | R4: 200000205 | S4: 05-04-2025 | T4: 0 | V4: 2013

Sheet 33
A1: Company Id | B1: Matched Id | C1: Status | D1: Classification | E1: Company Statement Type | F1: Company Invoice Date | G1: Company Invoice Number | H1: Company DocType | I1: Company Original DocType | J1: Company Amount | K1: Party Statement Type | L1: Party Invoice Date | M1: Party Invoice Number | N1: Party DocType | O1: Party Original DocType | P1: Party Amount | Q1: Difference | R1: Company Clearing Document Number | S1: Company Clearing Date | T1: Company TDS Amount | U1: Company Posting Date | V1: Company Code | W1: Supplier | X1: Document Number | Y1: Business Area | Z1: Assignment | AA1: Document Header Text | AB1: Tax Code | AC1: Year/Month | AD1: Reference | AE1: Profit Center | AF1: Posting Date | AG1: Amount in Doc. Curr. | AH1: Document Currency | AI1: Local Currency | AJ1: Entry Date | AK1: Withhldg Tax Base Amount | AL1: Payment Date
A2: 235e2d9d-0c3e-465a-bce7-c8540a216be3 | C2: Debit Note not booked by Party | D2: Unmatched | E2: ledger | F2: 19-09-2025 | H2: debitNote | I2: KG | J2: 17174.51 | P2: 0 | Q2: 17174.51 | R2: 7021002670 | T2: 0 | V2: EPL | W2: 708659 | X2: 7031002318 | Y2: EP00 | Z2: GJ2501024670-Rev | AA2: GJ2501024670-R | AB2: I5 | AC2: 2025/06 | AD2: EP22 | AE2: 7200 | AF2: 30-09-2025 | AG2: 17174.509999999998 | AH2: INR | AI2: INR | AJ2: 09-10-2025 | AK2: 14554.67 | AL2: 19-09-2025

Sheet 74
A1: Party Id | B1: Matched Id | C1: Status | D1: Classification | E1: Company Statement Type | F1: Company Invoice Date | G1: Company Invoice Number | H1: Company DocType | I1: Company Original DocType | J1: Company Amount | K1: Party Statement Type | L1: Party Invoice Date | M1: Party Invoice Number | N1: Party DocType | O1: Party Original DocType | P1: Party Amount | Q1: Difference | R1: Party Clearing Document Number | S1: Party Clearing Date | T1: Party TDS Amount | U1: Party Posting Date | V1: Profit Center | W1: Document Number | X1: Billing Document | Y1: Document Header Text
A2: 36a1e8bb-cb43-4030-b9bc-93be94971786 | C2: Other entry not booked by Company | D2: Unmatched | J2: 0 | K2: ledger | L2: 21-07-2025 | N2: clearing | O2: AB | P2: -38420.12 | Q2: -38420.12 | R2: 200037013 | S2: 21-07-2025 | T2: 0 | U2: 21-07-2025 | V2: 2011 | W2: 200037013
A3: 3d2dc23b-f138-4fd3-a676-b3237aac80b3 | C3: Other entry not booked by Company | D3: Unmatched | J3: 0 | K3: ledger | L3: 17-12-2025 | N3: clearing | O3: AB | P3: 8120 | Q3: 8120 | R3: 200098081 | S3: 17-12-2025 | T3: 0 | U3: 17-12-2025 | V3: 2011 | W3: 200098081
A4: 62292d65-5471-440c-b0ce-10489ac6d1fe | C4: Other entry not booked by Company | D4: Unmatched | J4: 0 | K4: ledger | L4: 08-01-2026 | N4: clearing | O4: AB | P4: 108280.51 | Q4: 108280.51 | R4: 200108729 | S4: 08-01-2026 | T4: 0 | U4: 08-01-2026 | V4: 2011 | W4: 200108729
A5: ba74d7a3-874f-4458-820c-6eb261c11d3f | C5: Other entry not booked by Company | D5: Unmatched | J5: 0 | K5: ledger | L5: 28-06-2025 | N5: clearing | O5: AB | P5: -8260 | Q5: -8260 | R5: 200025654 | S5: 28-06-2025 | T5: 0 | U5: 28-06-2025 | V5: 2011 | W5: 200025654
A6: f5fbf5ff-85d0-4195-8984-68ad1b83b9bb | C6: Other entry not booked by Company | D6: Unmatched | J6: 0 | K6: ledger | L6: 25-11-2025 | N6: clearing | O6: AB | P6: -24387.29 | Q6: -24387.29 | R6: 200088680 | S6: 25-11-2025 | T6: 0 | U6: 25-11-2025 | V6: 2011 | W6: 200088680
A7: 3122328d-4e8f-4214-b6ed-1a5d29b5e118 | C7: Other entry not booked by Company | D7: Unmatched | J7: 0 | K7: ledger | L7: 06-05-2025 | N7: clearing | O7: AB | P7: 95505.13 | Q7: 95505.13 | R7: 200009477 | S7: 06-05-2025 | T7: 0 | U7: 06-05-2025 | V7: 2013 | W7: 200009477
A8: 3169b1db-9463-45ca-97a4-c5f29e728e0c | C8: Other entry not booked by Company | D8: Unmatched | J8: 0 | K8: ledger | L8: 21-08-2025 | N8: clearing | O8: AB | P8: 8120 | Q8: 8120 | R8: 200048423 | S8: 21-08-2025 | T8: 0 | U8: 21-08-2025 | V8: 2011 | W8: 200048423
A9: 35d49a60-e57a-4c22-b647-7b09ecc744e9 | C9: Other entry not booked by Company | D9: Unmatched | J9: 0 | K9: ledger | L9: 29-01-2026 | N9: clearing | O9: AB | P9: -68999.12 | Q9: -68999.12 | R9: 200112844 | S9: 29-01-2026 | T9: 0 | U9: 29-01-2026 | V9: 2011 | W9: 200112844
A10: 56eeb852-d9c2-4387-9040-6f9c8a5b670b | C10: Other entry not booked by Company | D10: Unmatched | J10: 0 | K10: ledger | L10: 08-01-2026 | N10: clearing | O10: AB | P10: -108283.19 | Q10: -108283.19 | R10: 200108729 | S10: 08-01-2026 | T10: 0 | U10: 08-01-2026 | V10: 2011 | W10: 200108729
A11: 64ebcfa4-0b87-40d1-81d7-f6c16de835ac | C11: Other entry not booked by Company | D11: Unmatched | J11: 0 | K11: ledger | L11: 03-02-2026 | N11: clearing | O11: AB | P11: -334308.4 | Q11: -334308.4 | R11: 200123874 | S11: 03-02-2026 | T11: 0 | U11: 03-02-2026 | V11: 2013 | W11: 200123874
A12: 7a44f9d1-be29-4a3e-9782-fdb0cd6e60dc | C12: Other entry not booked by Company | D12: Unmatched | J12: 0 | K12: ledger | L12: 05-04-2025 | N12: clearing | O12: AB | P12: 61574 | Q12: 61574 | R12: 200000206 | S12: 05-04-2025 | T12: 0 | U12: 05-04-2025 | V12: 2013 | W12: 200000206
A13: 9ceb7afe-dcef-43db-a0db-27ef4899e2e0 | C13: Other entry not booked by Company | D13: Unmatched | J13: 0 | K13: ledger | L13: 12-11-2025 | N13: clearing | O13: AB | P13: -55804.07 | Q13: -55804.07 | R13: 200086152 | S13: 12-11-2025 | T13: 0 | U13: 12-11-2025 | V13: 2011 | W13: 200086152
... A29: fc59460b-31bc-459d-b137-e0efea74f193 | C29: Other entry not booked by Company | D29: Unmatched | J29: 0 | K29: ledger | L29: 06-05-2025 | N29: clearing | O29: AB | P29: -95507.05 | Q29: -95507.05 | R29: 200009477 | S29: 06-05-2025 | T29: 0 | U29: 06-05-2025 | V29: 2013 | W29: 200009477

Sheet 79
A1: Company Id | B1: Matched Id | C1: Status | D1: Classification | E1: Company Statement Type | F1: Company Invoice Date | G1: Company Invoice Number | H1: Company DocType | I1: Company Original DocType | J1: Company Amount | K1: Party Statement Type | L1: Party Invoice Date | M1: Party Invoice Number | N1: Party DocType | O1: Party Original DocType | P1: Party Amount | Q1: Difference | R1: Company Clearing Document Number | S1: Company Clearing Date | T1: Company TDS Amount | U1: Company Posting Date | V1: Company Code | W1: Supplier | X1: Document Number | Y1: Business Area | Z1: Assignment | AA1: Document Header Text | AB1: Tax Code | AC1: Year/Month | AD1: Reference | AE1: Profit Center | AF1: Posting Date | AG1: Amount in Doc. Curr. | AH1: Document Currency | AI1: Local Currency | AJ1: Entry Date | AK1: Withhldg Tax Base Amount | AL1: Payment Date
A2: 6f26c118-1932-4228-8692-f9f4c2aff5eb | C2: Other entry not booked by Party | D2: Unmatched | E2: ledger | F2: 19-09-2025 | H2: journal | I2: KA | J2: -17174.51 | P2: 0 | Q2: -17174.51 | R2: 7021002670 | T2: 0 | V2: EPL | W2: 708659 | X2: 7021002670 | Y2: EP00 | Z2: GJ2501024670-Rev | AA2: GJ2501024670-R | AB2: I5 | AC2: 2025/06 | AD2: EP22 | AE2: 7200 | AF2: 30-09-2025 | AG2: -17174.509999999998 | AH2: INR | AI2: INR | AJ2: 09-10-2025 | AK2: -14554.67 | AL2: 19-09-2025

Sheet 94
A1: Company Id | B1: Party Id | C1: Matched Id | D1: Status | E1: Classification | F1: Company Statement Type | G1: Company Invoice Date | H1: Company Invoice Number | I1: Company DocType | J1: Company Original DocType | K1: Company Narration | L1: Company Amount | M1: Party Statement Type | N1: Party Invoice Date | O1: Party Invoice Number | P1: Party DocType | Q1: Party Original DocType | R1: Party Narration | S1: Party Amount | T1: Difference
A2: 978a5118-8f9b-4f54-ab7b-de26a6e84029 | B2: 1753e470-c31e-44ee-8c22-932192d984dc | C2: 0ca1f6e1-3818-37d8-abe4-e28760ace981 | D2: TDS Booked by Company | E2: Invoice Number Matched | F2: ledger | G2: 05-07-2025 | H2: GJ2502001220 | I2: invoice | J2: MI | K2: Fixed facility charges july-25 | L2: -8120 | M2: ledger | N2: 05-07-2025 | O2: GJ2502001220 | P2: invoice | Q2: RV | S2: 8260 | T2: 140
A3: 81699d36-77e8-47e2-84b7-d79473efd7e7 | B3: 2f09a670-f8bb-488d-b481-f68bc079c1fb | C3: 7d8439fa-3569-3d4d-8e04-483f90e32539 | D3: TDS Booked by Company | E3: Invoice Number Matched | F3: ledger | G3: 05-09-2025 | H3: GJ2502001991 | I3: invoice | J3: MI | K3: Nitrogen charge for Sep 2025 | L3: -8120 | M3: ledger | N3: 05-09-2025 | O3: GJ2502001991 | P3: invoice | Q3: RV | S3: 8260 | T3: 140
A4: 1b2eed0c-69d7-4086-b222-84c806a0bc2d | B4: 52025ec7-6576-4532-96cb-3832f9894753 | C4: 60cba853-b0af-3a12-a105-b7ebec9ba82e | D4: TDS Booked by Company | E4: Invoice Number Matched | F4: ledger | G4: 05-04-2025 | H4: GJ2502000084 | I4: invoice | J4: MI | K4: Fixed Facility charges April-2025 | L4: -8120 | M4: ledger | N4: 05-04-2025 | O4: GJ2502000084 | P4: invoice | Q4: RV | S4: 8260 | T4: 140
A5: d84c105e-0d15-4c87-8093-51397aeeed96 | B5: 5bded08c-b8bb-4310-b6aa-84e43ea76a15 | C5: a812c24b-e13b-3e27-b92a-2cf60b3e73e8 | D5: TDS Booked by Company | E5: Invoice Number Matched | F5: ledger | G5: 05-12-2025 | H5: GJ2502003200 | I5: invoice | J5: MI | K5: Nitrogen charge for Dec 2025 | L5: -8120 | M5: ledger | N5: 05-12-2025 | O5: GJ2502003200 | P5: invoice | Q5: RV | S5: 8260 | T5: 140
A6: 13a89072-17f4-469b-adab-904e77bee999 | B6: 80f73e0c-33e6-46c1-8d62-587bbc3a6ddb | C6: 161da05b-906d-3575-9250-bfbc809ee54f | D6: TDS Booked by Company | E6: Invoice Number Matched | F6: ledger | G6: 05-02-2026 | H6: GJ2502003996 | I6: invoice | J6: MI | K6: Nitrogen tank 6kl Rent Charge (Inox) | L6: -29000 | M6: ledger | N6: 05-02-2026 | O6: GJ2502003996 | P6: invoice | Q6: RV | S6: 29500 | T6: 500
A7: b5bf1190-4f74-4bbe-a59f-dcb2eef139a5 | B7: 8eb60192-0029-4ab5-b967-7ae2120895a1 | C7: bd9d5fc0-06d9-3c2e-affe-610d3ee6c697 | D7: TDS Booked by Company | E7: Invoice Number Matched | F7: ledger | G7: 16-01-2026 | H7: GJ2502003786 | I7: invoice | J7: MI | K7: INSTALLATION & COMMISSIONING CHARGES | L7: -191400 | M7: ledger | N7: 16-01-2026 | O7: GJ2502003786 | P7: invoice | Q7: RV | S7: 194700 | T7: 3300
A8: 3940f24e-dfc9-4723-b284-a9633243c738 | B8: 9585cf72-7d9f-49d4-8de7-6598b9ef9d5b | C8: 91507aea-7dac-3408-967c-e19c93be9ccd | D8: TDS Booked by Company | E8: Invoice Number Matched | F8: ledger | G8: 05-05-2025 | H8: GJ2502000458 | I8: invoice | J8: MI | K8: YEARLY RENT CHARGES FOR NITROGEN MAY -25 | L8: -8120 | M8: ledger | N8: 05-05-2025 | O8: GJ2502000458 | P8: invoice | Q8: RV | S8: 8260 | T8: 140
A9: 2c198ecd-4da5-4e41-b2e0-1195d8b44afa | B9: a034260e-edf0-4c02-a6e0-6c3ea2bf4111 | C9: e9415d1a-cbd6-3be4-8bf0-91172cb5ed71 | D9: TDS Booked by Company | E9: Invoice Number Matched | F9: ledger | G9: 05-01-2026 | H9: GJ2502003741 | I9: invoice | J9: MI | K9: Nitrogen charge for Jan 2026 | L9: -8120 | M9: ledger | N9: 05-01-2026 | O9: GJ2502003741 | P9: invoice | Q9: RV | S9: 8260 | T9: 140
A10: a9dc7e96-48ff-47e7-95e7-1378163d69a3 | B10: bf5d9d3a-9642-4dec-a100-e2a69c626181 | C10: 12865390-331f-3113-9500-42d98c7e89c1 | D10: TDS Booked by Company | E10: Invoice Number Matched | F10: ledger | G10: 16-01-2026 | H10: GJ2502003787 | I10: invoice | J10: MI | K10: CONSULTANCY FEES- APPROX MONTH JAN 2025 | L10: -121800 | M10: ledger | N10: 16-01-2026 | O10: GJ2502003787 | P10: invoice | Q10: RV | S10: 123900 | T10: 2100
A11: 86801746-0a08-472a-81f9-c935168cb11d | B11: c8bc302e-567f-4af2-ad27-46d0ddb30d5c | C11: a906b5d9-6b60-38f2-ad22-63bc69ade4c6 | D11: TDS Booked by Company | E11: Invoice Number Matched | F11: ledger | G11: 05-08-2025 | H11: GJ2502001587 | I11: invoice | J11: MI | K11: FIXED FACILITY CHARGES FOR THE MONTH AUG 2025 | L11: -8120 | M11: ledger | N11: 05-08-2025 | O11: GJ2502001587 | P11: invoice | Q11: RV | S11: 8260 | T11: 140
A12: 51a92668-c8c7-4c24-9f2c-2631c3683758 | B12: cbb5426f-ca9b-4b03-b9c6-662f10c5e3d9 | C12: 91579428-4062-34c4-8fc3-25dd6e91e4e6 | D12: TDS Booked by Company | E12: Invoice Number Matched | F12: ledger | G12: 05-10-2025 | H12: GJ2502002394 | I12: invoice | J12: MI | K12: Nitrogen charge for Oct 2025 | L12: -8120 | M12: ledger | N12: 05-10-2025 | O12: GJ2502002394 | P12: invoice | Q12: RV | S12: 8260 | T12: 140
A13: 7ec3a1cb-0f6c-4ff9-9387-a76299ba90c2 | B13: d0115efd-f9dc-40ec-ba25-27535f0931c9 | C13: 89dac278-81b5-35a7-8dfb-4b95bb97a71d | D13: TDS Booked by Company | E13: Invoice Number Matched | F13: ledger | G13: 05-11-2025 | H13: GJ2502002813 | I13: invoice | J13: MI | K13: Nitrogen charge for Nov 2025 | L13: -8120 | M13: ledger | N13: 05-11-2025 | O13: GJ2502002813 | P13: invoice | Q13: RV | S13: 8260 | T13: 140
... A15: 2967a1fd-035c-4b49-8897-df1a4fef9b7d | B15: ff793414-4674-4195-a4cb-9916d8b4cffe | C15: 57b97990-b95b-3a06-9f29-8949bcacc33d | D15: TDS Booked by Company | E15: Invoice Number Matched | F15: ledger | G15: 05-01-2026 | H15: GJ2502003591 | I15: invoice | J15: MI | K15: Nitrogen tank 6kl Rent Charge (Inox) Month Jan 26 | L15: -29000 | M15: ledger | N15: 05-01-2026 | O15: GJ2502003591 | P15: invoice | Q15: RV | S15: 29500 | T15: 500
A16: 403538f4-e638-4059-b715-346bc44766df | B16: ab1cb182-2012-4bfc-9c4c-6a478cf177fa | C16: 5de0598d-fb5d-385d-83f5-f116f824a05e | D16: TDS Booked by Party | E16: Date and Amount Matched - Recommended | F16: ledger | G16: 02-03-2026 | H16: 7053062135 | I16: payment | J16: KZ | L16: 187950.57 | M16: ledger | N16: 02-03-2026 | P16: payment | Q16: DZ | S16: -188950.58 | T16: -1000.01

Sheet Party
A1: Party Id | B1: Matched Id | C1: Status | D1: Classification | E1: Party Statement Type | F1: Party Invoice Date | G1: Party Invoice Number | H1: Party DocType | I1: Party Original DocType | J1: Party Narration | K1: Party Amount | L1: Matched Rule | M1: Reco Data & Time | N1: Party Clearing Document Number | O1: Party Clearing Date | P1: Party TDS Amount | Q1: Party Posting Date | R1: Profit Center | S1: Document Number | T1: Billing Document | U1: Document Header Text
A2: 00568bd6-dc1e-4c1b-b3af-d340c62e09d7 | B2: 338d9c62-09dc-3c11-a8d5-39599d1733b2 | C2: Reconciled | D2: Invoice Number Matched | E2: ledger | F2: 31-12-2025 | G2: GJ2501039628 | H2: invoice | I2: RV | K2: 15498.94 | L2: PRI-INV1.5_A-company | M2: 03-Aug-26 04:10 PM | N2: 200111423 | O2: 21-01-2026 | P2: 0 | Q2: 31-12-2025 | R2: 2011 | S2: 322218 | T2: 95972934
A3: 011cc82e-ce12-4f07-9b59-8cb23954081c | B3: 411bb97f-154a-3e93-838a-aaf7cfc38ffc | C3: Reconciled | D3: Date and Amount Matched | E3: ledger | F3: 29-08-2025 | H3: payment | I3: DZ | J3: /103010300003186-AXIS Bank | K3: -56131.33 | L3: PRI-PAY10.1-company | M3: 03-Aug-26 04:10 PM | N3: 200051284 | O3: 30-08-2025 | P3: 0 | Q3: 29-08-2025 | R3: 2013 | S3: 1400048389 | U3: UTIBN62025082908954328
A4: 015634d8-09e8-4023-a05b-36d54c48610d | B4: bbc20328-c272-4c15-8e76-d77c91e4fb85 | C4: Reconciled | D4: Date Range and Amount Matched | E4: ledger | F4: 23-04-2025 | H4: payment | I4: DZ | J4: /103010300003186-AXIS Bank | K4: -43774.06 | L4: PRI-PAY11.1-company | M4: 03-Aug-26 04:10 PM | N4: 200002688 | O4: 23-04-2025 | P4: 0 | Q4: 23-04-2025 | R4: 2013 | S4: 1400005690 | U4: UTIBN62025042384063366
A5: 0320d7df-9a8d-4d25-9dc8-f3bc70fe582e | B5: 17c0c9f1-a4e5-32fd-b0c2-d53b07c35f44 | C5: Reconciled | D5: Invoice Number Matched | E5: ledger | F5: 01-02-2026 | G5: GJ2501044504 | H5: invoice | I5: RV | K5: 15289.51 | L5: PRI-INV1.5_A-company | M5: 03-Aug-26 04:10 PM | N5: 200127041 | O5: 14-02-2026 | P5: 0 | Q5: 01-02-2026 | R5: 2011 | S5: 360746 | T5: 96011469
A6: 03d61b08-0128-41ee-b955-5c4ff5560faa | B6: 40b161a7-aa6d-3a52-baad-50d925135767 | C6: Reconciled | D6: Date and Amount Matched | E6: ledger | F6: 09-05-2025 | H6: payment | I6: DZ | J6: /103010300003186-AXIS Bank | K6: -40841 | L6: PRI-PAY10.1-company | M6: 03-Aug-26 04:10 PM | N6: 200010428 | O6: 10-05-2025 | P6: 0 | Q6: 09-05-2025 | R6: 2013 | S6: 1400010998 | U6: UTIBN62025050950181213
A7: 04d81620-531e-4e19-88ee-107613bd869b | B7: 1389c6c3-a6c5-3e19-86d9-0c8da1f05247 | C7: Reconciled | D7: Invoice Number Matched | E7: ledger | F7: 27-08-2025 | G7: GJ2501021121 | H7: invoice | I7: RV | K7: 18431.19 | L7: PRI-INV1.5_A-company | M7: 03-Aug-26 04:10 PM | N7: 200058567 | O7: 16-09-2025 | P7: 0 | Q7: 27-08-2025 | R7: 2011 | S7: 172093 | T7: 95822724
A8: 05444b55-f170-4a18-ad36-24f0248b1ebf | B8: b1127b6c-9ebc-4778-9fbf-e92ccdeadead | C8: Reversal Entries | D8: Reversal Entries | E8: ledger | F8: 23-12-2025 | H8: clearing | I8: AB | K8: 28903 | L8: Pre-C-2.5_A-party | M8: 03-Aug-26 04:10 PM | N8: 200098952 | O8: 23-12-2025 | P8: 0 | Q8: 23-12-2025 | R8: 2011 | S8: 200098952
A9: 06072f9e-bce9-434a-834b-92937774341f | B9: a417e015-dd65-3146-aeed-78a488b1d737 | C9: Reconciled | D9: Date and Amount Matched | E9: ledger | F9: 08-04-2025 | H9: payment | I9: DZ | J9: /103010300003186-AXIS Bank | K9: -13404.5 | L9: PRI-PAY10.1-company | M9: 03-Aug-26 04:10 PM | N9: 200000551 | O9: 09-04-2025 | P9: 0 | Q9: 08-04-2025 | R9: 2013 | S9: 1400001752 | U9: UTIBN62025040818050778
A10: 06e0e672-43c3-46b9-bef2-8955ab2f6fbc | B10: d32111f5-e80a-3091-9ae1-5eff9d9b7249 | C10: Reconciled | D10: Date and Amount Matched | E10: ledger | F10: 20-10-2025 | H10: payment | I10: DZ | J10: /103010300003186-AXIS Bank | K10: -55503 | L10: PRI-PAY10.1-company | M10: 03-Aug-26 04:10 PM | N10: 200070021 | O10: 21-10-2025 | P10: 0 | Q10: 20-10-2025 | R10: 2013 | S10: 1400064794 | U10: UTIBN62025102095960257
A11: 0796d026-0402-413a-9301-cde53584fdb6 | B11: 4533fbb2-4143-4323-8a7d-4373f5657fa5 | C11: Reversal Entries | D11: Reversal Entries | E11: ledger | F11: 17-10-2025 | H11: clearing | I11: AB | K11: 18012 | L11: Pre-C-2.5_A-party | M11: 03-Aug-26 04:10 PM | N11: 200069296 | O11: 17-10-2025 | P11: 0 | Q11: 17-10-2025 | R11: 2011 | S11: 200069296
A12: 07b100d4-c250-4300-8bf1-8b6771cee943 | B12: ba553ae6-3bf4-3417-bc98-6fd9f305c957 | C12: Reconciled | D12: Date and Amount Matched | E12: ledger | F12: 29-07-2025 | H12: payment | I12: DZ | J12: /103010300003186-AXIS Bank | K12: -89013.58 | L12: PRI-PAY10.1-company | M12: 03-Aug-26 04:10 PM | N12: 200040134 | O12: 30-07-2025 | P12: 0 | Q12: 29-07-2025 | R12: 2013 | S12: 1400037857 | U12: UTIBN62025072982287240
A13: 08c9ed73-272a-49ec-9eb4-14d127952f20 | B13: 563737e2-2fb6-3c3d-a9de-2c77a62ceafd | C13: Reconciled | D13: Date and Amount Matched | E13: ledger | F13: 02-07-2025 | H13: payment | I13: DZ | J13: /103010300003186-AXIS Bank | K13: -46496.71 | L13: PRI-PAY10.1-company | M13: 03-Aug-26 04:10 PM | N13: 200029663 | O13: 03-07-2025 | P13: 0 | Q13: 02-07-2025 | R13: 2013 | S13: 1400028635 | U13: UTIBN62025070286926749
A14: 0949c732-28f6-4691-a576-a552862c67ce | B14: b9e8bf13-4417-3227-93d5-5160ea9dd12c | C14: Reconciled | D14: Date and Amount Matched | E14: ledger | F14: 11-02-2026 | H14: payment | I14: DZ | J14: /103010300003186-AXIS Bank | K14: -29950.67 | L14: PRI-PAY10.1-company | M14: 03-Aug-26 04:10 PM | N14: 200126611 | O14: 12-02-2026 | P14: 0 | Q14: 11-02-2026 | R14: 2013 | S14: 1400102560 | U14: AXISCN1249138144
A15: 0a0321c6-89f7-4c57-92de-8c4a76028ad3 | B15: f005b7c9-4b76-4cb4-99ba-d36255f5622f | C15: Reversal Entries | D15: Reversal Entries | E15: ledger | F15: 04-12-2025 | H15: clearing | I15: AB | K15: -14451.72 | L15: Pre-C-2.5_A-party | M15: 03-Aug-26 04:10 PM | N15: 200095703 | O15: 04-12-2025 | P15: 0 | Q15: 04-12-2025 | R15: 2011 | S15: 200095703
A16: 0a81d059-bc80-4f29-a70b-678a8c49cc0f | B16: b5a9f204-b92c-4cd8-80fa-11ab7201ec58 | C16: Reversal Entries | D16: Reversal Entries | E16: ledger | F16: 25-12-2025 | H16: clearing | I16: AB | K16: -29531.78 | L16: Pre-C-2.5_A-party | M16: 03-Aug-26 04:10 PM | N16: 200099446 | O16: 25-12-2025 | P16: 0 | Q16: 25-12-2025 | R16: 2011 | S16: 200099446
A17: 0c684ffc-6023-45f7-85f0-055ee52a6186 | B17: 70dac47e-b423-466c-8f46-117c51994a19 | C17: Reversal Entries | D17: Reversal Entries | E17: ledger | F17: 20-08-2025 | H17: clearing | I17: AB | K17: 25342 | L17: Pre-C-2.5_A-party | M17: 03-Aug-26 04:10 PM | N17: 200048357 | O17: 20-08-2025 | P17: 0 | Q17: 20-08-2025 | R17: 2011 | S17: 200048357
A18: 0d9f589f-e950-45e5-b567-4ad370ba9d5b | B18: 64e94695-6d05-3c53-adbf-ddefe5825ad9 | C18: Write off / Rounding off | D18: Invoice Number Matched | E18: ledger | F18: 08-08-2025 | G18: GJ2501018486 | H18: invoice | I18: RV | K18: 13823.4 | L18: PRI-INV1.5-company | M18: 03-Aug-26 04:10 PM | N18: 200048357 | O18: 20-08-2025 | P18: 0 | Q18: 08-08-2025 | R18: 2011 | S18: 152011 | T18: 95802632
A19: 0e2b51ec-62d9-4d6c-a760-1630824582c2 | B19: a01ded7b-10cf-490e-b332-b7882fd57180 | C19: Reversal Entries | D19: Reversal Entries | E19: ledger | F19: 31-07-2025 | H19: clearing | I19: AB | K19: -68069.73 | L19: Pre-C-2.5_A-party | M19: 03-Aug-26 04:10 PM | N19: 200041895 | O19: 31-07-2025 | P19: 0 | Q19: 31-07-2025 | R19: 2011 | S19: 200041895
